Workbook

Sheet Reporte de vacaciones 1
B1: REPORTE DE VACACIONES
B2: EMPLEADOS | C2: FECHA DE INGRESO A RUAG | D2: Fecha de ingreso a planilla | E2: Años correspondiente a vacaciones | F2: Días de vacaciones | G2: Derecho a días de vacaciones | H2: 44119 | I2: Gozados (2012) | J2: Enero - diciembre 2013 | V2: Gozadas (2013) | W2: Enero - diciembre 2014 | AI2: Gozadas (2014) | AJ2: Enero - diciembre 2015 | AV2: Gozadas (2015) | AW2: Enero - diciembre 2016 | BI2: Gozadas (2016) | BJ2: Enero - diciembre 2017 | BV2: Gozadas (2017) | BW2: Enero - diciembre 2018 | CI2: Gozadas (2018) | CJ2: Enero - diciembre 2019 | CV2: Gozadas (2019) | CW2: Enero - diciembre 2020 | DI2: Gozadas (2020 | DJ2: Total días gozados | DK2: PENDIENTE POR GOZAR
H3: Derecho a días de vacaciones
J4: ENE | K4: FEB | L4: MAR | M4: ABR | N4: MAY | O4: JUN | P4: JUL | Q4: AGO | R4: SEP | S4: OCT | T4: NOV | U4: DIC | W4: ENE | X4: FEB | Y4: MAR | Z4: ABR | AA4: MAY | AB4: JUN | AC4: JUL | AD4: AGO | AE4: SEP | AF4: OCT | AG4: NOV | AH4: DIC | AJ4: ENE | AK4: FEB | AL4: MAR | AM4: ABR | AN4: MAY | AO4: JUN | AP4: JUL | AQ4: AGO | AR4: SEP | AS4: OCT | AT4: NOV | AU4: DIC | AW4: ENE | AX4: FEB | AY4: MAR | AZ4: ABR | BA4: MAY | BB4: JUN | BC4: JUL | BD4: AGO | BE4: SEP | BF4: OCT | BG4: NOV | BH4: DIC | BJ4: ENE | BK4: FEB | BL4: MAR | BM4: ABR | BN4: MAY | BO4: JUN | BP4: JUL | BQ4: AGO | BR4: SEP | BS4: OCT | BT4: NOV | BU4: DIC | BW4: ENE | BX4: FEB | BY4: MAR | BZ4: ABR | CA4: MAY | CB4: JUN | CC4: JUL | CD4: AGO | CE4: SEP | CF4: OCT | CG4: NOV | CH4: DIC | CJ4: ENE | CK4: FEB | CL4: MAR | CM4: ABR | CN4: MAY | CO4: JUN | CP4: JUL | CQ4: AGO | CR4: SEP | CS4: OCT | CT4: NOV | CU4: DIC | CW4: ENE | CX4: FEB | CY4: MAR | CZ4: ABR | DA4: MAY | DB4: JUN | DC4: JUL | DD4: AGO | DE4: SEP | DF4: OCT | DG4: NOV | DH4: DIC
A5: 1 | B5: ALARCON PEREZ LUIS | C5: 42736 | D5: 01/01/2017 | E5: 01 ene 2017 al 31 dic 2017 | F5: 30 | G5: =+F5+F6+F8+F7 -> 90 | BO5: 1 | BS5: 1 | BU5: 6 | BV5: =BU5+BS5+BO5 -> 8 | BY5: 1 | CB5: 1 | CC5: 1 | CE5: 7 | CF5: =2+1 -> 3 | CI5: =SUM(BW5:CH8) -> 13 | CV5: =SUM(CJ5:CU8) -> 0 | CW5: 1 | DE5: 9 | DI5: =SUM(CW5:DH8) -> 10 | DJ5: =I5+V5+AI5+AV5+BI5+BV5+CI5+CV5+DI5 -> 31
E6: 01 ene 2018 al 31 dic 2018 | F6: 30 | H6: =ROUNDDOWN((H2-D5)/365,0)*30 -> 90 | DK6: =H6-DJ5 -> 59
E7: 01 ene 2019 al 31 dic 2019 | F7: 30
E8: 01 Ene 2020 al 31 Dic 2020
A9: 3 | B9: ALEJOS TORIBIO, SULELMA MELISA | C9: 01/09/2017 | D9: 01/09/2017 | E9: 01 set 2017 al 31 ago 2018 | F9: 30 | G9: =F9+F10+F11 -> 90 | BS9: 1 | BV9: =SUM(BJ10:BU10) -> 1 | BY9: 1 | BZ9: 2 | CA9: 2 | CB9: 2 | CI9: =SUM(BW9:CH11) -> 7 | CP9: 1 | CU9: 1 | CV9: =SUM(CJ9:CU11) -> 2 | DE9: 13 | DF9: 1 | DI9: =SUM(CW9:DH11) -> 14 | DJ9: =I9+V9+AI9+AV9+BI9+BV9+CI9+CV9+DI9 -> 24 | DK9: =H10-DJ9 -> 66
E10: 01 set 2018 al 31 ago 2019 | F10: 30 | H10: =ROUNDDOWN(($H$2-D9)/365,0)*30 -> 90 | BU10: 1
E11: 01 set 2019 al 31 ago 2020 | F11: 30
A12: 2 | B12: ALHUAY AYESTA, RAMIRO | D12: 01/09/2014 | E12: 01 Set 2014 al 30 Ago 2015 Gozado | F12: 30 | G12: =F12+F13+F17+F14+F15+F16 -> 180 | V12: =SUM(J12:U17) -> 0 | AF12: 5 | AH12: 10 | AI12: =SUM(W12:AH17) -> 15 | AK12: 1 | AM12: 3 | AO12: 6 | AP12: 2 | AQ12: 1 | AV12: =SUM(AJ12:AU17) -> 13 | BG12: 1 | BH12: 15 | BI12: =SUM(AW12:BH17) -> 16 | BM12: 2 | BU12: 6 | BV12: =SUM(BJ12:BU17) -> 8 | BX12: 2 | BZ12: 7 | CD12: 1 | CF12: 3 | CH12: 11 | CI12: =SUM(BW12:CH17) -> 24 | CO12: 15 | CP12: 7 | CR12: 14 | CU12: 12 | CV12: =SUM(CJ12:CU17) -> 48 | CX12: 4 | DF12: 31 | DI12: =SUM(CW12:DH17) -> 35 | DJ12: =I12+V12+AI12+AV12+BI12+BV12+CI12+CV12+DI12 -> 159 | DK12: =H14-DJ12 -> 21
E13: 01 Set 2015 al 30 Ago 2016 Gozado | F13: 30
E14: 01 Set 2016 al 30 Ago 2017 Gozado | F14: 30 | H14: =ROUNDDOWN(($H$2-D12)/365,0)*30 -> 180
E15: 01 Set 2017 al 30 Ago 2018 Gozado | F15: 30
E16: 01 Set 2018 al 30 Ago 2019 Gozados | F16: 30
E17: 01 Set 2019 al 30 Ago 2020 | F17: 30
A18: 4 | B18: ALTAMIRANO SULCA MANUEL | C18: 16/05/2012 BAJA | D18: 01/08/2018 | E18: 01 Ago 2018 al 31 Jul 2019 | F18: 30 | G18: =F18+F19+F20+F21 -> 60 | V18: =SUM(J18:U21) -> 0 | AI18: =SUM(W18:AH21) -> 0 | AV18: =SUM(AJ18:AU21) -> 0 | BG18: 1 | BH18: 7 | CJ18: 14 | CV18: =SUM(CJ18:CU21) -> 14 | DI18: =SUM(CW18:DH21) -> 0 | DJ18: =CV18 -> 14 | DK18: =H20-DJ18 -> 46
C19: 01/02/2019 BAJA | E19: 01 Ago 2019 al 31 Jul 2020 | F19: 30
H20: =ROUNDDOWN(($H$2-D18)/365,0)*30 -> 60
A22: 4 | B22: ARROYO FALLA, VANESSA ALICIA | C22: 16/05/2012 BAJA | D22: 01/04/2019 | E22: 01 abr 2019 al 31 mar 2020 | F22: 30 | G22: =F22+F23+F24+F25 -> 30 | V22: =SUM(J22:U25) -> 0 | AI22: =SUM(W22:AH25) -> 0 | AV22: =SUM(AJ22:AU25) -> 0 | BG22: 1 | BH22: 7 | CP22: 10 | CQ22: 7 | CV22: =SUM(CJ22:CU25) -> 17 | CX22: 10 | CY22: 11 | DI22: =SUM(CW22:DH25) -> 21 | DJ22: =CV22+DI22 -> 38 | DK22: =H24-DJ22 -> -8
C23: 01/02/2019 BAJA
H24: =ROUNDDOWN(($H$2-D22)/365,0)*30 -> 30
A26: 5 | B26: ASPILCUETA GUTIERREZ KAREN | C26: 01 abril 2013 | D26: 01/04/2013 | E26: 01 Abr 2013 al 30 Mar 2014 Gozado | F26: 30 | G26: =F26+F27+F28+F29+F30+F31 -> 180 | N26: 1 | V26: =SUM(J26:U31) -> 1 | AD26: 7 | AH26: 1 | AI26: =SUM(W26:AH31) -> 8 | AJ26: 1 | AK26: 4 | AL26: 2 | AN26: 1 | AP26: 1 | AS26: 1 | AU26: 3 | AV26: =SUM(AJ26:AU31) -> 13 | AW26: 2 | AX26: 1 | AZ26: 1 | BA26: 7 | BC26: 2 | BD26: 1 | BG26: 1 | BH26: 1 | BI26: =SUM(AW26:BH31) -> 16 | BJ26: 2 | BK26: 7 | BM26: 1 | BO26: 1 | BP26: 1 | BQ26: 1 | BS26: 2 | BT26: 1 | BU26: 8 | BV26: =SUM(BJ26:BU31) -> 24 | BW26: 13 | BX26: 1 | CA26: 1 | CC26: 8 | CE26: 1 | CH26: 2 | CI26: =SUM(BW26:CH31) -> 26 | CK26: 7 | CO26: 1 | CP26: 10 | CQ26: 1 | CU26: 1 | CV26: =SUM(CJ26:CU31) -> 20 | CX26: 7 | CY26: 8 | DE26: 15 | DI26: =SUM(CW26:DH31) -> 30 | DJ26: =V26+AI26+AV26+BI26+BV26+CI26+CV26+DI26 -> 138 | DK26: =H29-DJ26 -> 72
E27: 01 Abr 2014 al 30 Mar 2015 Gozado | F27: 30
E28: 01 Abr 2016 al 30 Mar 2017 Gozado | F28: 30
E29: 01 Abr 2017 al 30 Mar 2018 | F29: 30 | H29: =ROUNDDOWN(($H$2-D26)/365,0)*30 -> 210
E30: 01 Abr 2018 al 30 Mar 2019 | F30: 30
E31: 01 Abr 2019 al 30 Mar 2020 | F31: 30
A32: 6 | B32: BACA WIESSE JOSE ALBERTO | C32: 01 junio 2005 | D32: 01/01/2011 | E32: 01 Ene 2011 al 31 Dic 2011 Gozado | F32: 30 | G32: =F32+F33+F34+F35+F36+F37+F38+F39+F40 -> 270 | I32: 45 | K32: 1 | M32: 1 | O32: 4 | P32: 1 | Q32: 3 | U32: 1 | V32: =SUM(J32:U41) -> 11 | W32: 1 | X32: 1 | Z32: 1 | AA32: 4 | AE32: 1 | AF32: 1 | AH32: 3 | AI32: =SUM(W32:AH41) -> 12 | AK32: 4 | AM32: 1 | AO32: 4 | AP32: 2 | AR32: 1 | AS32: 4 | AT32: 1 | AU32: 3 | AV32: =SUM(AJ32:AU41) -> 20 | AX32: 14 | AY32: 2 | BF32: 1 | BG32: 3 | BH32: 3 | BI32: =SUM(AW32:BH41) -> 23 | BV32: =SUM(BJ32:BU41) -> 0 | BX32: 10 | CC32: 1 | CD32: 1 | CI32: =SUM(BW32:CH41) -> 12 | CK32: 11 | CU32: 14 | CV32: =SUM(CJ32:CU41) -> 25 | CX32: 12 | DE32: 15 | DF32: 15 | DI32: =SUM(CW32:DH41) -> 42 | DJ32: =I32+V32+AI32+AV32+BI32+BV32+CI32+CV32+DI32 -> 190 | DK32: =H37-DJ32 -> 80
E33: 01 Ene 2012 al 31 Dic 2012 Gozado | F33: 30
E34: 01 Ene 2013 al 31 Dic 2013 Gozado | F34: 30
E35: 01 Ene 2014 al 31 Dic 2014 Gozado | F35: 30
E36: 01 Ene 2015 al 31 Dic 2015 Gozado | F36: 30
E37: 01 Ene 2016 al 31 Dic 2016 | F37: 30 | H37: =ROUNDDOWN(($H$2-D32)/365,0)*30 -> 270
E38: 01 Ene 2017 al 31 Dic 2017 | F38: 30
E39: 01 Ene 2018 al 31 Dic 2018 | F39: 30
E40: 01 Ene 2019 al 31 Dic 2019 | F40: 30
E41: 01 Ene 2020 al 31 Dic 2020
A42: 7 | B42: BALLENA CASTILLO ITALA ADRIANA | C42: 01 febrero 2010 | D42: 01/03/2011 | E42: 01 Mar 2011 al 28 Feb 2012 gozado | F42: 30 | G42: =F42+F43+F44+F45+F46+F47+F48+F49+F50 -> 270 | I42: 15 | L42: 5 | O42: 5 | P42: 8 | V42: =SUM(J42:U50) -> 18 | AD42: 2 | AE42: 1 | AH42: 3 | AI42: =SUM(W42:AH50) -> 6 | AJ42: 1 | AK42: 15 | AP42: 4 | AQ42: 1 | AV42: =SUM(AJ42:AU50) -> 21 | BB42: 14 | BD42: 1 | BH42: 22 | BI42: =SUM(AW42:BH50) -> 37 | BQ42: 37 | BS42: 1 | BU42: 14 | BV42: =SUM(BJ42:BU50) -> 52 | BW42: 4 | CF42: 30 | CI42: =SUM(BW42:CH50) -> 34 | CM42: 3 | CR42: 8 | CU42: 15 | CV42: =SUM(CJ42:CU50) -> 26 | DI42: =SUM(CW42:DH50) -> 0 | DJ42: =I42+V42+AI42+AV42+BI42+BV42+CI42+CV42+DI42 -> 209 | DK42: =H46-DJ42 -> 61
...

Sheet control de vacaciones
D1: 44119
B2: VACACIONES EMPLEADOS | D2: PENDIENTE POR GOZAR DÍAS
A3: 24 | B3: 1 | C3: ALARCON PEREZ LUIS | D3: ='Reporte de vacaciones 1'!DK6 -> 59
A4: 32 | B4: 2 | C4: ALEJOS TORIBIO, SULELMA MELISA | D4: ='Reporte de vacaciones 1'!DK9 -> 66
A5: 34 | B5: 3 | C5: ALHUAY AYESTA, RAMIRO | D5: ='Reporte de vacaciones 1'!DK12 -> 21
A6: 31 | B6: 4 | C6: ALTAMIRANO SULCA MANUEL | D6: ='Reporte de vacaciones 1'!DK18 -> 46
A7: 16 | B7: 5 | C7: ARROYO FALLA, VANESSA ALICIA | D7: ='Reporte de vacaciones 1'!DK22 -> -8
A8: 7 | B8: 6 | C8: ASPILCUETA GUTIERREZ KAREN | D8: ='Reporte de vacaciones 1'!DK26 -> 72
A9: 13 | B9: 7 | C9: BACA WIESSE JOSE ALBERTO | D9: ='Reporte de vacaciones 1'!DK32 -> 80
A10: 33 | B10: 8 | C10: BALLENA CASTILLO ITALA ADRIANA | D10: ='Reporte de vacaciones 1'!DK42 -> 61
A11: 6 | B11: 9 | C11: BAUTISTA AYESTA HEBER | D11: ='Reporte de vacaciones 1'!DK51 -> 205
A12: 22 | B12: 10 | C12: BAUTISTA AYESTA WALTER | D12: ='Reporte de vacaciones 1'!DK60 -> 264
A13: 9 | B13: 11 | C13: BRIONES RIVERA, RICHARD | D13: ='Reporte de vacaciones 1'!DK69 -> 0
A14: 4 | B14: 12 | C14: COLETO PASTOR LUIS ENRIQUE | D14: ='Reporte de vacaciones 1'!DK78 -> 70
A15: 27 | B15: 13 | C15: CORDOVA VELEZ, JULISSA | D15: ='Reporte de vacaciones 1'!DK87 -> 0
A16: 5 | B16: 14 | C16: DAMBROSIO RIVERO LIZETH STEFANNY | D16: ='Reporte de vacaciones 1'!DK96 -> -10
A17: 4 | B17: 15 | C17: ESPEJO PACHECO, URSULA AMELIA
A18: 3 | B18: 16 | C18: FLORES GUARDIA CLAUDIA | D18: ='Reporte de vacaciones 1'!DK101 -> -18
A19: 10 | B19: 17 | C19: FLORES MANTILLA MARIANA | D19: ='Reporte de vacaciones 1'!DK107 -> 63
A20: 18 | B20: 18 | C20: GOYAS ABRAMONTE, JAVIER ENRRIQUE | D20: ='Reporte de vacaciones 1'!DK113 -> 30
A21: 17 | B21: 19 | C21: GRANDE ALCANTARA GERMAN N. | D21: ='Reporte de vacaciones 1'!DK119 -> 180
A22: 23 | B22: 20 | C22: GRANDE ALCANTARA MILAGROS M. | D22: ='Reporte de vacaciones 1'!DK128 -> 142
A23: 1 | B23: 21 | C23: GRANDE ALCANTARA PAUL | D23: ='Reporte de vacaciones 1'!DK133 -> 91
A24: 2 | B24: 22 | C24: GRANDE ALCANTRA, RAUL NEVADA
B25: 23 | C25: GRANDE PECEROS DAVID | D25: ='Reporte de vacaciones 1'!DK142 -> 13
A26: 8 | B26: 24 | C26: JUAN PEDRO CRUZ, GIOVANNA PAULA | D26: ='Reporte de vacaciones 1'!DK146 -> -9
A27: 19 | B27: 25 | C27: MENDOZA GARCÍA, ZINCIA | D27: ='Reporte de vacaciones 1'!DK155 -> -8
A28: 33 | B28: 26 | C28: OCHOA GUTIERREZ ERICKSON | D28: ='Reporte de vacaciones 1'!DK158 -> 30
A29: 29 | B29: 27 | C29: OROSCO BALAREZO SILVIA | D29: ='Reporte de vacaciones 1'!DK164 -> 0
A30: 12 | B30: 28 | C30: OSCCO GUILLEN EDWIN RAFAEL | D30: ='Reporte de vacaciones 1'!DK170 -> 0
A31: 221 | B31: 29 | C31: OSCCO GUILLEN ZORAIDA | D31: ='Reporte de vacaciones 1'!DK176 -> 56
A32: 24 | B32: 30 | C32: PEÑA HERNANDEZ, FERNANDO FAVIAN | D32: ='Reporte de vacaciones 1'!DK184 -> 74
B33: 31 | C33: RAMIREZ ROMAN MARCELO | D33: ='Reporte de vacaciones 1'!DK187 -> 152
B34: 32 | C34: REYNA COSTA CLARA | D34: ='Reporte de vacaciones 1'!DK196 -> -18
B35: 33 | C35: SALIRROSSA PONCE LILIANA | D35: ='Reporte de vacaciones 1'!DK199 -> 0
B36: 34 | C36: TERRONES BECERRA MARISSA | D36: ='Reporte de vacaciones 1'!DK202 -> 127
B37: 35 | C37: TOMAYLLA TERRONES KATHERINE | D37: ='Reporte de vacaciones 1'!DK211 -> 137
B38: 36 | C38: VENEGAS MARCHAND, FRANCISCO MARTIN | D38: ='Reporte de vacaciones 1'!DK217 -> 30
B39: 37 | C39: YNCIO JIMENEZ SILVIA | D39: ='Reporte de vacaciones 1'!DK223 -> -19
B40: 38 | C40: YON UTRILLA LUIS | D40: ='Reporte de vacaciones 1'!DK226 -> 6
...

Sheet Reporte de vacaciones  (2)
B1: REPORTE DE VACACIONES | I1: 2019 | K1: 2020 | N1: 2021
B2: EMPLEADOS | C2: FECHA DE INGRESO A RUAG | D2: Fecha de ingreso a planilla | E2: Años correspondiente a vacaciones | F2: Días de vacaciones | G2: Derecho a días de vacaciones | H2: Fecha de ingreso a planilla (covid-19) | K2: NO AFECTO A COVID | L2: AFECTO A COVID | P2: 44132 | Q2: Gozados (2012) | R2: Enero - diciembre 2013 | AD2: Gozadas (2013) | AE2: Enero - diciembre 2014 | AQ2: Gozadas (2014) | AR2: Enero - diciembre 2015 | BD2: Gozadas (2015) | BE2: Enero - diciembre 2016 | BQ2: Gozadas (2016) | BR2: Enero - diciembre 2017 | CD2: Gozadas (2017) | CE2: Enero - diciembre 2018 | CQ2: Gozadas (2018) | CR2: Enero - diciembre 2019 | DD2: Gozadas (2019) | DE2: Enero - diciembre 2020 | DQ2: Gozadas (2020 | DS2: Dias no trabajados X COVID | DT2: Fecha de ingreso a planilla (covid-19) | DU2: 2021 | DW2: 44130 | DX2: Total días gozados | DY2: PENDIENTE POR GOZAR | DZ2: PROYECTADO | EN2: Total días gozados
P3: Derecho a días de vacaciones | DW3: Derecho a días de vacaciones | DZ3: 2020 | EB3: 2021
R4: ENE | S4: FEB | T4: MAR | U4: ABR | V4: MAY | W4: JUN | X4: JUL | Y4: AGO | Z4: SEP | AA4: OCT | AB4: NOV | AC4: DIC | AE4: ENE | AF4: FEB | AG4: MAR | AH4: ABR | AI4: MAY | AJ4: JUN | AK4: JUL | AL4: AGO | AM4: SEP | AN4: OCT | AO4: NOV | AP4: DIC | AR4: ENE | AS4: FEB | AT4: MAR | AU4: ABR | AV4: MAY | AW4: JUN | AX4: JUL | AY4: AGO | AZ4: SEP | BA4: OCT | BB4: NOV | BC4: DIC | BE4: ENE | BF4: FEB | BG4: MAR | BH4: ABR | BI4: MAY | BJ4: JUN | BK4: JUL | BL4: AGO | BM4: SEP | BN4: OCT | BO4: NOV | BP4: DIC | BR4: ENE | BS4: FEB | BT4: MAR | BU4: ABR | BV4: MAY | BW4: JUN | BX4: JUL | BY4: AGO | BZ4: SEP | CA4: OCT | CB4: NOV | CC4: DIC | CE4: ENE | CF4: FEB | CG4: MAR | CH4: ABR | CI4: MAY | CJ4: JUN | CK4: JUL | CL4: AGO | CM4: SEP | CN4: OCT | CO4: NOV | CP4: DIC | CR4: ENE | CS4: FEB | CT4: MAR | CU4: ABR | CV4: MAY | CW4: JUN | CX4: JUL | CY4: AGO | CZ4: SEP | DA4: OCT | DB4: NOV | DC4: DIC | DE4: ENE | DF4: FEB | DG4: MAR | DH4: ABR | DI4: MAY | DJ4: JUN | DK4: JUL | DL4: AGO | DM4: SEP | DN4: OCT | DO4: NOV | DP4: DIC | DZ4: NOV | EA4: DIC | EB4: ENE | EC4: FEB | ED4: MAR | EE4: ABR | EF4: MAY | EG4: JUN | EH4: JUL | EI4: AGO | EJ4: SET | EK4: OCT | EL4: NOV | EM4: DIC
A5: 1 | B5: ALARCON PEREZ LUIS | C5: 42736 | D5: 01/01/2017 | E5: 01 ene 2017 al 31 dic 2017 | F5: 30 | G5: =+F5+F6+#REF!+#REF! -> #REF! | H5: 42792 | I5: =+D5+3*360 -> 43816 | J5: 90 | K5: =+I5+360 -> 44176 | L5: =K5+DS5 -> 44232 | M5: 0 | N5: 44232 | P5: =ROUNDDOWN((P2-D5)/365,0)*30 -> 90 | BW5: 1 | CA5: 1 | CC5: 6 | CD5: =CC5+CA5+BW5 -> 8 | CG5: 1 | CJ5: 1 | CK5: 1 | CM5: 7 | CN5: =2+1 -> 3 | CQ5: =SUM(CE5:CP6) -> 13 | DD5: =SUM(CR5:DC6) -> 0 | DE5: 1 | DM5: 9 | DQ5: =SUM(DE5:DP6) -> 10 | DS5: ='Determ días de vacaciones'!S10 -> 56 | DT5: =K5+DS5 -> 44232 | DW5: =ROUNDDOWN(($DW$2-H5)/365,0)*30 -> 90 | DX5: =Q5+AD5+AQ5+BD5+BQ5+CD5+CQ5+DD5+DQ5 -> 31 | DY5: =P5-DX5 -> 59 | DZ5: 15 | EA5: 15 | EB5: 15 | EC5: 14 | EN5: =SUM(DZ5:EM6) -> 59
E6: 01 ene 2018 al 31 dic 2018 | F6: 30
A7: 2 | B7: ALEJOS TORIBIO, SULELMA MELISA | C7: 01/09/2017 | D7: 01/09/2017 | E7: 01 set 2017 al 31 ago 2018 | F7: 30 | G7: =F7+F8+#REF! -> #REF! | H7: 43071 | I7: =+D7+2*360 -> 43699 | J7: 60 | K7: =I7+360 -> 44059 | L7: =K7+DS7 -> 44151 | M7: 0 | N7: =+L7+360 -> 44511 | P7: =ROUNDDOWN(($P$2-D7)/365,0)*30 -> 90 | CA7: 1 | CD7: =SUM(BR8:CC8) -> 1 | CG7: 1 | CH7: 2 | CI7: 2 | CJ7: 2 | CQ7: =SUM(CE7:CP8) -> 7 | CX7: 1 | DC7: 1 | DD7: =SUM(CR7:DC8) -> 2 | DM7: 13 | DN7: 1 | DQ7: =SUM(DE7:DP8) -> 14 | DS7: ='Determ días de vacaciones'!S11 -> 92 | DW7: =ROUNDDOWN(($DW$2-H7)/365,0)*30 -> 60 | DX7: =Q7+AD7+AQ7+BD7+BQ7+CD7+CQ7+DD7+DQ7 -> 24 | DY7: =P7-DX7 -> 66 | DZ7: 15 | EA7: 15 | EB7: 15 | EC7: 15 | ED7: 6 | EN7: =SUM(DZ7:EM8) -> 66
E8: 01 set 2018 al 31 ago 2019 | F8: 30 | CC8: 1
A9: 3 | B9: ALHUAY AYESTA, RAMIRO | D9: 01/09/2014 | E9: 01 Set 2014 al 30 Ago 2015 Gozado | F9: 30 | G9: =F9+F10+#REF!+#REF!+#REF!+#REF! -> #REF! | H9: 41975 | I9: =+D9+5*360 -> 43683 | J9: 150 | K9: =I9+360 -> 44043 | L9: =K9+DS9 -> 44135 | M9: 0 | N9: =+L9+360 -> 44495 | P9: =ROUNDDOWN(($P$2-D9)/365,0)*30 -> 180 | AD9: =SUM(R9:AC10) -> 0 | AN9: 5 | AP9: 10 | AQ9: =SUM(AE9:AP10) -> 15 | AS9: 1 | AU9: 3 | AW9: 6 | AX9: 2 | AY9: 1 | BD9: =SUM(AR9:BC10) -> 13 | BO9: 1 | BP9: 15 | BQ9: =SUM(BE9:BP10) -> 16 | BU9: 2 | CC9: 6 | CD9: =SUM(BR9:CC10) -> 8 | CF9: 2 | CH9: 7 | CL9: 1 | CN9: 3 | CP9: 11 | CQ9: =SUM(CE9:CP10) -> 24 | CW9: 15 | CX9: 7 | CZ9: 14 | DC9: 12 | DD9: =SUM(CR9:DC10) -> 48 | DF9: 4 | DN9: 31 | DQ9: =SUM(DE9:DP10) -> 35 | DS9: ='Determ días de vacaciones'!S12 -> 92 | DW9: =ROUNDDOWN(($DW$2-H9)/365,0)*30 -> 150 | DX9: =Q9+AD9+AQ9+BD9+BQ9+CD9+CQ9+DD9+DQ9 -> 159 | DY9: =P9-DX9 -> 21 | DZ9: 21 | EN9: =SUM(DZ9:EM10) -> 21
E10: 01 Set 2015 al 30 Ago 2016 Gozado | F10: 30
A11: 4 | B11: ALTAMIRANO SULCA MANUEL | C11: 16/05/2012 BAJA | D11: 01/08/2018 | E11: 01 Ago 2018 al 31 Jul 2019 | F11: 30 | G11: =F11+F12+#REF!+#REF! -> #REF! | H11: 43375 | I11: =+D11+360 -> 43673 | J11: 30 | K11: =I11+360 -> 44033 | L11: =K11+DS11 -> 44095 | M11: 30 | N11: =+L11+360 -> 44455 | P11: =ROUNDDOWN(($P$2-D11)/365,0)*30 -> 60 | AD11: =SUM(R11:AC12) -> 0 | AQ11: =SUM(AE11:AP12) -> 0 | BD11: =SUM(AR11:BC12) -> 0 | BO11: 1 | BP11: 7 | CR11: 14 | DD11: =SUM(CR11:DC12) -> 14 | DQ11: =SUM(DE11:DP12) -> 0 | DS11: ='Determ días de vacaciones'!S13 -> 62 | DW11: =ROUNDDOWN(($DW$2-H11)/365,0)*30 -> 60 | DX11: =DD11 -> 14 | DY11: =P11-DX11 -> 46 | DZ11: 30 | EA11: 16 | EN11: =SUM(DZ11:EM12) -> 46
C12: 01/02/2019 BAJA | E12: 01 Ago 2019 al 31 Jul 2020 | F12: 30
A13: 5 | B13: ARROYO FALLA, VANESSA ALICIA | C13: 16/05/2012 BAJA | D13: 01/04/2019 | E13: 01 abr 2019 al 31 mar 2020 | F13: 30 | G13: =F13+F14+#REF!+#REF! -> #REF! | H13: 43986 | K13: =+D13+360 -> 43916 | L13: =K13+DS13 -> 43980 | M13: 30 | N13: =+L13+360 -> 44340 | P13: =ROUNDDOWN(($P$2-D13)/365,0)*30 -> 30 | AD13: =SUM(R13:AC14) -> 0 | AQ13: =SUM(AE13:AP14) -> 0 | BD13: =SUM(AR13:BC14) -> 0 | BO13: 1 | BP13: 7 | CX13: 10 | CY13: 7 | DD13: =SUM(CR13:DC14) -> 17 | DF13: 10 | DG13: 11 | DQ13: =SUM(DE13:DP14) -> 21 | DS13: 64 | DW13: =ROUNDDOWN(($DW$2-H13)/365,0)*30 -> 0 | DX13: =DD13+DQ13 -> 38 | DY13: =P13-DX13 -> -8 | EN13: =SUM(DZ13:EM14) -> 0
C14: 01/02/2019 BAJA
A15: 6 | B15: ASPILCUETA GUTIERREZ KAREN | C15: 01 abril 2013 | D15: 01/04/2013 | E15: 01 Abr 2013 al 30 Mar 2014 Gozado | F15: 30 | G15: =F15+F16+#REF!+#REF!+#REF!+#REF! -> #REF! | H15: 41406 | I15: =+D15+6*360 -> 43525 | J15: 180 | K15: =I15+360 -> 43885 | M15: 30 | N15: =+K15+DS15+360 -> 44286 | P15: =ROUNDDOWN(($P$2-D15)/365,0)*30 -> 210 | V15: 1 | AD15: =SUM(R15:AC16) -> 1 | AL15: 7 | AP15: 1 | AQ15: =SUM(AE15:AP16) -> 8 | AR15: 1 | AS15: 4 | AT15: 2 | AV15: 1 | AX15: 1 | BA15: 1 | BC15: 3 | BD15: =SUM(AR15:BC16) -> 13 | BE15: 2 | BF15: 1 | BH15: 1 | BI15: 7 | BK15: 2 | BL15: 1 | BO15: 1 | BP15: 1 | BQ15: =SUM(BE15:BP16) -> 16 | BR15: 2 | BS15: 7 | BU15: 1 | BW15: 1 | BX15: 1 | BY15: 1 | CA15: 2 | CB15: 1 | CC15: 8 | CD15: =SUM(BR15:CC16) -> 24 | CE15: 13 | CF15: 1 | CI15: 1 | CK15: 8 | CM15: 1 | CP15: 2 | CQ15: =SUM(CE15:CP16) -> 26 | CS15: 7 | CW15: 1 | CX15: 10 | CY15: 1 | DC15: 1 | DD15: =SUM(CR15:DC16) -> 20 | DF15: 7 | DG15: 8 | DM15: 15 | DQ15: =SUM(DE15:DP16) -> 30 | DS15: ='Determ días de vacaciones'!S15 -> 41 | DW15: =ROUNDDOWN(($DW$2-H15)/365,0)*30 -> 210 | DX15: =AD15+AQ15+BD15+BQ15+CD15+CQ15+DD15+DQ15 -> 138 | DY15: =P15-DX15 -> 72 | DZ15: 15 | EA15: 15 | EB15: 15 | EC15: 15 | ED15: 12 | EN15: =SUM(DZ15:EM16) -> 72
E16: 01 Abr 2014 al 30 Mar 2015 Gozado | F16: 30
A17: 7 | B17: BACA WIESSE JOSE ALBERTO | C17: 01 junio 2005 | D17: 01/01/2011 | E17: 01 Ene 2011 al 31 Dic 2011 Gozado | F17: 30 | G17: =F17+F18+#REF!+#REF!+#REF!+#REF!+#REF!+#REF!+#REF! -> #REF! | H17: 40605 | I17: =+D17+9*360 -> 43784 | J17: 270 | K17: =I17+360 -> 44144 | L17: =K17+DS17 -> 44206 | M17: 0 | N17: 44206 | P17: =ROUNDDOWN(($P$2-D17)/365,0)*30 -> 270 | Q17: 45 | S17: 1 | U17: 1 | W17: 4 | X17: 1 | Y17: 3 | AC17: 1 | AD17: =SUM(R17:AC18) -> 11 | AE17: 1 | AF17: 1 | AH17: 1 | AI17: 4 | AM17: 1 | AN17: 1 | AP17: 3 | AQ17: =SUM(AE17:AP18) -> 12 | AS17: 4 | AU17: 1 | AW17: 4 | AX17: 2 | AZ17: 1 | BA17: 4 | BB17: 1 | BC17: 3 | BD17: =SUM(AR17:BC18) -> 20 | BF17: 14 | BG17: 2 | BN17: 1 | BO17: 3 | BP17: 3 | BQ17: =SUM(BE17:BP18) -> 23 | CD17: =SUM(BR17:CC18) -> 0 | CF17: 10 | CK17: 1 | CL17: 1 | CQ17: =SUM(CE17:CP18) -> 12 | CS17: 11 | DC17: 14 | DD17: =SUM(CR17:DC18) -> 25 | DF17: 12 | DM17: 15 | DN17: 15 | DQ17: =SUM(DE17:DP18) -> 42 | DS17: ='Determ días de vacaciones'!S16 -> 62 | DT17: =K17+DS17 -> 44206 | DW17: =ROUNDDOWN(($DW$2-H17)/365,0)*30 -> 270 | DX17: =Q17+AD17+AQ17+BD17+BQ17+CD17+CQ17+DD17+DQ17 -> 190 | DY17: =P17-DX17 -> 80 | DZ17: 15 | EA17: 15 | EB17: 15 | EC17: 15 | ED17: 15 | EE17: 5 | EN17: =SUM(DZ17:EM18) -> 80
E18: 01 Ene 2012 al 31 Dic 2012 Gozado | F18: 30
A19: 8 | B19: BALLENA CASTILLO ITALA ADRIANA | C19: 01 febrero 2010 | D19: 01/03/2011 | E19: 01 Mar 2011 al 28 Feb 2012 gozado | F19: 30 | G19: =F19+F20+#REF!+#REF!+#REF!+#REF!+#REF!+#REF!+#REF! -> #REF! | H19: 40647 | I19: =+D19+8*360 -> 43483 | J19: 240 | K19: =I19+360 -> 43843 | M19: 30 | N19: =+K19+DS19+360 -> 44247 | P19: =ROUNDDOWN(($P$2-D19)/365,0)*30 -> 270 | Q19: 15 | T19: 5 | W19: 5 | X19: 8 | AD19: =SUM(R19:AC20) -> 18 | AL19: 2 | AM19: 1 | AP19: 3 | AQ19: =SUM(AE19:AP20) -> 6 | AR19: 1 | AS19: 15 | AX19: 4 | AY19: 1 | BD19: =SUM(AR19:BC20) -> 21 | BJ19: 14 | BL19: 1 | BP19: 22 | BQ19: =SUM(BE19:BP20) -> 37 | BY19: 37 | CA19: 1 | CC19: 14 | CD19: =SUM(BR19:CC20) -> 52 | CE19: 4 | CN19: 30 | CQ19: =SUM(CE19:CP20) -> 34 | CU19: 3 | CZ19: 8 | DC19: 15 | DD19: =SUM(CR19:DC20) -> 26 | DQ19: =SUM(DE19:DP20) -> 0 | DS19: ='Determ días de vacaciones'!S17 -> 44 | DT19: =K19+DS19 -> 43887 | DW19: =ROUNDDOWN(($DW$2-H19)/365,0)*30 -> 270 | DX19: =Q19+AD19+AQ19+BD19+BQ19+CD19+CQ19+DD19+DQ19 -> 209 | DY19: =P19-DX19 -> 61 | DZ19: 30 | EA19: 31 | EN19: =SUM(DZ19:EM20) -> 61
E20: 01 Mar 2012 al 28 Feb 2013 gozado | F20: 30
A21: 9 | B21: BAUTISTA AYESTA HEBER (INGRESO PLANILLA 01/07/2007) | C21: 01 agosto 2005 | D21: 01/07/2011 | E21: 01 Jul 2011 al 30 Jun 2012 Gozado | F21: 30 | G21: =F21+F22+#REF!+#REF!+#REF!+#REF!+#REF!+#REF!+#REF! -> #REF! | H21: 40787 | I21: =+D21+8*360 -> 43605 | J21: 240 | K21: =I21+360 -> 43965 | L21: =K21+DS21 -> 44027 | M21: 30 | N21: =+L21+360 -> 44387 | P21: =ROUNDDOWN(($P$2-D21)/365,0)*30 -> 270 | Q21: 15 | AD21: =SUM(R21:AC22) -> 0 | AQ21: =SUM(AE21:AP21) -> 0 | AS21: 14 | BD21: =SUM(AR21:BC21) -> 14 | BF21: 1 | BH21: 1 | BJ21: 5 | BQ21: =SUM(BE21:BP21) -> 7 | CD21: =SUM(BR21:CC21) -> 0 | CG21: 15 | CQ21: =SUM(CE21:CP21) -> 15 | CX21: 14 | DD21: =SUM(CR21:DC21) -> 14 | DQ21: =SUM(DE21:DP21) -> 0 | DS21: ='Determ días de vacaciones'!S18 -> 62 | DW21: =ROUNDDOWN(($DW$2-H21)/365,0)*30 -> 270 | DX21: =Q21+AD21+AQ21+BD21+BQ21+CD21+CQ21+DD21+DQ21 -> 65 | DY21: =P21-DX21 -> 205 | DZ21: 30 | EA21: 31 | EB21: 31 | EC21: 28 | ED21: 31 | EE21: 30 | EF21: 24 | EN21: =SUM(DZ21:EM22) -> 205
E22: 01 Jul 2012 al 30 Jun 2013 Gozado | F22: 30
A23: 10 | B23: BAUTISTA AYESTA WALTER (INGRESO A PLANILLA 01/05/2007) | C23: 01 agosto 2005 | D23: 01/05/2011 | E23: 01 May 2011 al 30 Abr 2012 | F23: 30 | G23: =F23+F24+#REF!+#REF!+#REF!+#REF!+#REF!+#REF!+#REF! -> #REF! | H23: 40756 | I23: =+D23+8*360 -> 43544 | J23: 240 | K23: =I23+360 -> 43904 | M23: 30 | N23: =K23+DS23+360 -> 44356 | P23: =ROUNDDOWN(($P$2-D23)/365,0)*30 -> 270 | AD23: =SUM(R23:AC24) -> 0 | AQ23: =SUM(AE23:AP23) -> 0 | AW23: 6 | BD23: =SUM(AR23:BC23) -> 6 | BQ23: =SUM(BE23:BP23) -> 0 | CD23: =SUM(BR23:CC23) -> 0 | CQ23: =SUM(CE23:CP23) -> 0 | DD23: =SUM(CR23:DC23) -> 0 | DQ23: =SUM(DE23:DP23) -> 0 | DS23: ='Determ días de vacaciones'!S19 -> 92 | DW23: =ROUNDDOWN(($DW$2-H23)/365,0)*30 -> 270 | DX23: =SUM(BD23,BQ23) -> 6 | DY23: =P23-DX23 -> 264 | DZ23: 30 | EA23: 31 | EB23: 31 | EC23: 28 | ED23: 31 | EE23: 30 | EF23: 31 | EG23: 30 | EH23: 22 | EN23: =SUM(DZ23:EM24) -> 264
E24: 01 May 2012 al 30 Abr 2013 | F24: 30
A25: 11 | B25: BRIONES RIVERA, RICHARD | C25: 01 enero 2009 | D25: 01/02/2020 | G25: =F25+F26+#REF!+#REF!+#REF!+#REF!+#REF!+#REF!+#REF! -> #REF! | K25: 01/02/2020 | M25: 0 | N25: =+K25+DS25+360 -> 44359 | P25: =ROUNDDOWN(($P$2-D25)/365,0)*30 -> 0 | DS25: ='Determ días de vacaciones'!S20 -> 137 | DX25: =Q25+AD25+AQ25+BD25+BQ25+CD25+CQ25+DD25 -> 0 | DY25: =P25-DX25 -> 0 | EN25: =SUM(DZ25:EM26) -> 0
A27: 12 | B27: COLETO PASTOR LUIS ENRIQUE (INGRESO A PLANILLA 01/10/2010) | D27: 01/10/2011 | E27: 01 Oct 2011 al 30 Set 2012 Gozado | F27: 30 | G27: =F27+F28+#REF!+#REF!+#REF!+#REF!+#REF!+#REF!+#REF! -> #REF! | H27: 40544 | I27: =+D27+8*360 -> 43697 | J27: 240 | K27: =I27+360 -> 44057 | L27: =K27+DS27 -> 44149 | M27: 0 | N27: =+L27+360 -> 44509 | P27: =ROUNDDOWN(($P$2-D27)/365,0)*30 -> 270 | AD27: =SUM(R27:AC28) -> 0 | AE27: 10 | AL27: 16 | AM27: 30 | AN27: 30 | AQ27: =SUM(AE27:AP27) -> 86 | AY27: 3 | BA27: 23 | BC27: 1 | BD27: =SUM(AR27:BC27) -> 27 | BE27: 1 | BO27: 1 | BQ27: =SUM(BE27:BP27) -> 2 | BT27: 7 | CC27: 4 | CD27: =SUM(BR27:CC27) -> 11 | CE27: 54 | CQ27: =SUM(CE27:CP27) -> 54 | CX27: 9 | DB27: 11 | DD27: =SUM(CR27:DC27) -> 20 | DQ27: =SUM(DE27:DP27) -> 0 | DS27: ='Determ días de vacaciones'!S21 -> 92 | DW27: =ROUNDDOWN(($DW$2-H27)/365,0)*30 -> 270 | DX27: =Q27+AD27+AQ27+BD27+BQ27+CD27+CQ27+DD27 -> 200 | DY27: =P27-DX27 -> 70 | DZ27: 30 | EA27: 31 | EB27: 9 | EN27: =SUM(DZ27:EM28) -> 70
E28: 01 Oct 2012 al 30 Set 2013 Gozado | F28: 30
A29: 13 | B29: CORDOVA VELEZ, JULISSA | C29: 01 abril 2011 | D29: 01/02/2020 | G29: =F29+F30+#REF!+#REF!+#REF!+#REF!+#REF!+#REF! -> #REF! | K29: 01/02/2020 | M29: 0 | N29: =+K29+DS29+360 -> 44359 | P29: =ROUNDDOWN(($P$2-D29)/365,0)*30 -> 0 | X29: 15 | AC29: 7 | DS29: ='Determ días de vacaciones'!S22 -> 137 | DX29: =AD29+AQ29+BD29+BQ29+CD29+CQ29+DD29+DQ29 -> 0 | DY29: =P29-DX29 -> 0 | EN29: =SUM(DZ29:EM30) -> 0
A31: 14 | B31: DAMBROSIO RIVERO LIZETH STEFANNY | C31: 01 marzo 2007 | D31: 01/01/2019 | E31: 01 ene 2019 al 31 Dic 2019 | F31: 30 | G31: =F31+F32+#REF!+#REF!+#REF! -> #REF! | H31: 43561 | I31: =+D31+360 -> 43826 | J31: 30 | K31: 43831 | M31: 30 | N31: =K31+DS31+360 -> 44287 | P31: =ROUNDDOWN(($P$2-D31)/365,0)*30 -> 30 | AD31: =SUM(R31:AC31) -> 0 | AK31: 1 | BD31: =SUM(AR31:BC31) -> 0 | BQ31: =SUM(BE31:BP31) -> 0 | CD31: =SUM(BR31:CC32) -> 0 | CQ31: =SUM(CE31:CP32) -> 0 | CV31: 3 | DC31: 4 | DD31: =SUM(CR31:DC32) -> 7 | DL31: 31 | DM31: 2 | DQ31: =SUM(DE31:DP32) -> 33 | DS31: 96 | DT31: =K31+DS31 -> 43927 | DW31: =ROUNDDOWN(($DW$2-H31)/365,0)*30 -> 30 | DX31: =Q31+AD31+AQ31+BD31+BQ31+CD31+CQ31+DD31+DQ31 -> 40 | DY31: =P31-DX31 -> -10 | EN31: =SUM(DZ31:EM32) -> 0
E32: 1 ene 2020 al 31 Dic 2020
A33: 15 | B33: FLORES GUARDIA CLAUDIA | C33: 01 marzo 2007 | D33: 01/11/2019 | E33: 01 nov 2019 al 31 oct 2020 | F33: 30 | G33: =F33+F34+#REF!+#REF!+#REF!+#REF! -> #REF! | K33: 44136 | L33: =+K33+DS33 -> 44206 | M33: 0 | N33: 44206 | P33: =ROUNDDOWN(($P$2-D33)/365,0)*30 -> 0 | DM33: 18 | DQ33: =SUM(DE33:DP34) -> 18 | DS33: 70 | DT33: =K33+DS33 -> 44206 | DX33: =Q33+AD33+AQ33+BD33+BQ33+CD33+CQ33+DD33+DQ33 -> 18 | DY33: =P33-DX33 -> -18 | EN33: =SUM(DZ33:EM34) -> 0
A35: 16 | B35: FLORES MANTILLA MARIANA | C35: 01 marzo 2007 | D35: 01/07/2014 | E35: 01 Jul 2014 al 30 Jun 2015 Gozado | F35: 30 | G35: =F35+F36+#REF!+#REF!+#REF!+#REF! -> #REF! | H35: 41898 | I35: =+D35+5*360 -> 43621 | J35: 150 | K35: =I35+360 -> 43981 | L35: =K35+DS35 -> 44058 | M35: 30 | N35: =+L35+360 -> 44418 | P35: =ROUNDDOWN(($P$2-D35)/365,0)*30 -> 180 | AD35: =SUM(R35:AC35) -> 0 | AK35: 1 | AQ35: =SUM(AK35:AP36) -> 1 | AS35: 30 | AT35: 30 | AX35: 1 | BD35: =SUM(AR35:BC35) -> 61 | BF35: 7 | BK35: 3 | BO35: 1 | BQ35: =SUM(BE35:BP35) -> 11 | BV35: 1 | BX35: 1 | CC35: 1 | CD35: =SUM(BR35:CC36) -> 3 | CF35: 1 | CG35: 7 | CK35: 7 | CN35: 8 | CQ35: =SUM(CE35:CP36) -> 23 | CT35: 1 | CW35: 7 | CX35: 2 | DD35: =SUM(CR35:DC36) -> 10 | DF35: 6 | DN35: 2 | DQ35: =SUM(DE35:DP36) -> 8 | DS35: ='Determ días de vacaciones'!S26 -> 77 | DW35: =ROUNDDOWN(($DW$2-H35)/365,0)*30 -> 180 | DX35: =Q35+AD35+AQ35+BD35+BQ35+CD35+CQ35+DD35+DQ35 -> 117 | DY35: =P35-DX35 -> 63 | DZ35: 30 | EA35: 31 | EB35: 2 | EN35: =SUM(DZ35:EM36) -> 63
E36: 01 Jul 2015 al 30 Jun 2016 Gozado | F36: 30
A37: 17 | B37: GOYAS ABRAMONTE JAVIER | C37: 01 marzo 2007 | D37: 01/04/2019 | E37: 01 Abr 2019 al 30 Mar 2020 | F37: 30 | G37: =F37+F38+#REF!+#REF!+#REF!+#REF! -> #REF! | H37: 43600 | K37: 43922 | L37: =K37+DS37 -> 43966 | M37: 30 | N37: =+L37+360 -> 44326 | P37: =ROUNDDOWN(($P$2-D37)/365,0)*30 -> 30 | DQ37: =SUM(DE37:DP38) -> 0 | DS37: ='Determ días de vacaciones'!S27 -> 44 | DW37: =ROUNDDOWN(($DW$2-H37)/365,0)*30 -> 30 | DX37: =Q37+AD37+AQ37+BD37+BQ37+CD37+CQ37+DD37+DQ37 -> 0 | DY37: =P37-DX37 -> 30 | DZ37: 30 | EN37: =SUM(DZ37:EM38) -> 30
A39: 18 | B39: GRANDE ALCANTARA GERMAN N. (INGRESO A PLANILLA 01/04/2007) | D39: 01/04/2011 | E39: 01 Abr 2011 al 30 Mar 2012 Gozado | F39: 30 | G39: =F39+F40+#REF!+#REF!+#REF!+#REF!+#REF!+#REF!+#REF! -> #REF! | H39: 40675 | I39: =+D39+8*360 -> 43514 | J39: 240 | K39: =I39+360 -> 43874 | M39: 30 | N39: =K39+DS39+360 -> 44275 | P39: =ROUNDDOWN(($P$2-D39)/365,0)*30 -> 270 | AD39: =SUM(R39:AC40) -> 0 | AQ39: =SUM(AE39:AP40) -> 0 | AS39: 7 | AV39: 2 | BD39: =SUM(AR39:BC40) -> 9 | BE39: 20 | BO39: 1 | BQ39: =SUM(BE39:BP40) -> 21 | BV39: 7 | BX39: 20 | CD39: =SUM(BR39:CC40) -> 27 | CQ39: =SUM(CE39:CP40) -> 0 | DD39: =SUM(CR39:DC40) -> 0 | DH39: 30 | DM39: 3 | DQ39: =SUM(DE39:DP40) -> 33 | DS39: ='Determ días de vacaciones'!S28 -> 41 | DW39: =ROUNDDOWN(($DW$2-H39)/365,0)*30 -> 270 | DX39: =SUM(AD39,AQ39,BD39,BQ39,CD39,CQ39:CQ39,DD39,DQ39) -> 90 | DY39: =P39-DX39 -> 180 | DZ39: 15 | EA39: 15 | EB39: 15 | EC39: 15 | ED39: 15 | EE39: 15 | EF39: 15 | EG39: 15 | EH39: 15 | EI39: 15 | EJ39: 15 | EK39: 15 | EN39: =SUM(DZ39:EM40) -> 180
E40: 01 Abr 2012 al 30 Mar 2013 | F40: 30
A41: 19 | B41: GRANDE ALCANTARA MILAGROS M. (INGRESO PLANILLA 01/07/2008) | D41: 01/07/2011 | E41: 01 Jul 2011 al 30 Jun 2012 Gozado | F41: 30 | G41: =F41+F42+#REF!+#REF!+#REF!+#REF!+#REF!+#REF!+#REF! -> #REF! | H41: 40781 | I41: =+D41+8*360 -> 43605 | J41: 240 | K41: =I41+360 -> 43965 | L41: =K41+DS41 -> 44021 | M41: 30 | N41: =+L41+360 -> 44381 | P41: =ROUNDDOWN(($P$2-D41)/365,0)*30 -> 270 | Q41: 15 | AD41: =SUM(R41:AC42) -> 0 | AQ41: =SUM(AE41:AP42) -> 0 | AS41: 8 | AX41: 8 | BD41: =SUM(AR41:BC42) -> 16 | BO41: 1 | BQ41: =SUM(BE41:BP42) -> 1 | BX41: 10 | CD41: =SUM(BR41:CC42) -> 10 | CF41: 5 | CQ41: =SUM(CE41:CP42) -> 5 | CR41: 30 | DD41: =SUM(CR41:DC42) -> 30 | DE41: 31 | DN41: 20 | DQ41: =SUM(DE41:DP42) -> 51 | DS41: ='Determ días de vacaciones'!S29 -> 56 | DW41: =ROUNDDOWN(($DW$2-H41)/365,0)*30 -> 270 | DX41: =Q41+AD41+AQ41+BD41+BQ41+CD41+CQ41+DD41+DQ41 -> 128 | DY41: =P41-DX41 -> 142 | DZ41: 30 | EA41: 31 | EB41: 31 | EC41: 28 | ED41: 22 | EN41: =SUM(DZ41:EM42) -> 142
E42: 01 Jul 2012 al 30 Jun 2013 Gozado | F42: 30
A43: 20 | B43: GRANDE ALCANTARA PAUL | D43: 01/01/2012 | E43: 01 Ene 2012 al 30 Dic 2012 Gozado | F43: 30 | G43: =F43+F44+#REF!+#REF!+#REF!+#REF!+#REF!+#REF!+F45 -> #REF! | H43: 40956 | I43: =+D43+8*360 -> 43789 | J43: 240 | K43: =I43+360 -> 44149 | L43: =+K43+DS43 -> 44196 | M43: 0 | N43: =+L43+360 -> 44556 | P43: =ROUNDDOWN(($P$2-D43)/365,0)*30 -> 240 | Q43: 15 | AD43: =SUM(R43:AC44) -> 0 | AE43: 4 | AI43: 3 | AQ43: =SUM(AE43:AP44) -> 7 | AS43: 7 | AW43: 7 | BB43: 2 | BC43: 3 | BD43: =SUM(AR43:BC44) -> 19 | BE43: 10 | BF43: 2 | BK43: 7 | BQ43: =SUM(BE43:BP44) -> 19 | BS43: 2 | CD43: =SUM(BS43:CC44) -> 2 | CG43: 6 | CH43: 8 | CQ43: =SUM(CG43:CP44) -> 14 | CY43: 12 | DD43: =SUM(CT43:DC44) -> 12 | DM43: 30 | DN43: 31 | DQ43: =SUM(DG43:DP44) -> 61 | DS43: ='Determ días de vacaciones'!S30 -> 47 | DT43: =K43+DS43 -> 44196 | DW43: =ROUNDDOWN(($DW$2-H43)/365,0)*30 -> 240 | DX43: =Q43+AD43+AQ43+BD43+BQ43+CD43+CQ43+DD43+DQ43 -> 149 | DY43: =P43-DX43 -> 91 | DZ43: 30 | EA43: 31 | EB43: 30 | EN43: =SUM(DZ43:EM44) -> 91
E44: 01 Ene 2013 al 30 Dic 2013 Gozado | F44: 30
...

Sheet vacaciones 2026
B1: REPORTE DE VACACIONES
B2: EMPLEADOS | D2: SALDOS DE DIAS POR GOZAR 2025 | E2: ENE | F2: FEB | G2: MAR | H2: ABR | I2: MAY | J2: JUN | K2: JUL | L2: AGO | M2: SET | N2: OCT | O2: NOV | P2: DIC | Q2: Total días gozados | R2: PENDIENTES POR GOZAR 2025 | S2: FECHAS DE VENCIMIENTO 2026 | T2: VACACIONES POR VENCER 2026 | U2: Vacaciones Pendientes por gozar 2026
B3: AREA DE GERENCIA
A4: 2 | B4: ASPILCUETA GUTIERREZ KAREN | C4: ASISTENTE GERENCIAL | D4: 120 | F4: 1 | G4: 1 | Q4: =SUM(E4:P4) -> 2 | R4: =+D4-Q4 -> 118 | S4: 46113 | T4: 30 | U4: =+R4+T4 -> 148
A5: 3 | B5: GRANDE PECEROS DAVID | C5: ADMINISTRADOR | D5: 44 | G5: 2 | Q5: =SUM(E5:P5) -> 2 | R5: =+D5-Q5 -> 42 | S5: 46296 | U5: =+R5+T5 -> 42
A6: 1 | B6: GRANDE ALCANTRA, RAUL NEVADA | C6: GERENTE GENERAL | D6: ='vacaciones 2023 '!U6 -> 0 | Q6: =SUM(E6:P6) -> 0 | R6: =+D6-Q6 -> 0 | U6: =+R6+T6 -> 0
B7: AREA DE PRESUPUESTO
A8: 7 | B8: YON UTRILLA LUIS | C8: ARQUITECTO | D8: 143 | Q8: =SUM(E8:P8) -> 0 | R8: =+D8-Q8 -> 143 | S8: 46311 | U8: =+R8+T8 -> 143
B9: VENEGAS MARCHAND FRANCISCO | C9: ING. CIVIL | D9: 9 | G9: 7 | Q9: =SUM(E9:P9) -> 7 | R9: =+D9-Q9 -> 2 | S9: 46235 | U9: =+R9+T9 -> 2
B10: ROMERO ARROYO, VALERIE FERNANDA | C10: ARQUITECTO | S10: 46388
B11: OCHOA GUTIERREZ ERICKSON | C11: ING. CIVIL | D11: -5 | Q11: =SUM(E11:P11) -> 0 | R11: =+D11-Q11 -> -5 | S11: 46102 | T11: 30 | U11: =+R11+T11 -> 25
B12: AREA DE OPERACIONES
A13: 11 | B13: ARROYO FALLA, VANESSA ALICIA | C13: ARQUITECTA | D13: 21 | Q13: =SUM(E13:P13) -> 0 | R13: =+D13-Q13 -> 21 | S13: 46113 | U13: =+R13+T13 -> 21 | W13: =W12-#REF!+1 -> #REF!
A14: 12 | B14: BAUTISTA MOLINA LUIS FERNANDO | C14: ING. CIVIL | D14: 148 | Q14: =SUM(E14:P14) -> 0 | R14: =+D14-Q14 -> 148 | S14: 46327 | U14: =+R14+T14 -> 148
B15: BRAVO GARCIA CESAR OMAR | C15: ARQUITECTO | D15: 0 | E15: 5 | Q15: =SUM(E15:P15) -> 5 | R15: =+D15-Q15 -> -5 | S15: 46054 | T15: 30 | U15: =+R15+T15 -> 25
A16: 13 | B16: BRIONES RIVERA, RICHARD | C16: ARQUITECTO | D16: 9 | Q16: =SUM(E16:P16) -> 0 | R16: =+D16-Q16 -> 9 | S16: 46054 | T16: 30 | U16: =+R16+T16 -> 39 | W16: 45996
B17: CARRANZA HOYOS GUILLERMO | C17: ING. CIVIL | D17: 30 | Q17: =SUM(E17:P17) -> 0 | R17: =+D17-Q17 -> 30 | S17: 46267 | U17: =+R17+T17 -> 30
B18: CASTRO VALERIO HASSANAL | C18: ARQUITECTO | D18: 0 | Q18: =SUM(E18:P18) -> 0 | R18: =+D18-Q18 -> 0 | S18: 46489 | U18: =+R18+T18 -> 0
B19: CHUMBIAUCA URIBE, JOSE CARLOS | C19: ING. CIVIL | D19: 0 | Q19: =SUM(E19:P19) -> 0 | R19: =+D19-Q19 -> 0 | S19: 46450 | U19: =+R19+T19 -> 0
A20: 14 | B20: COLETO PASTOR LUIS ENRIQUE | C20: ING. CIVIL | D20: 0 | Q20: =SUM(E20:P20) -> 0 | R20: =+D20-Q20 -> 0 | S20: 46023 | T20: 30 | U20: =+R20+T20 -> 30 | W20: 45983
B21: CUEVA RIVAS, JORGE ARMANDO | C21: ING. CIVIL | D21: 0 | Q21: =SUM(E21:P21) -> 0 | R21: =+D21-Q21 -> 0 | S21: 46442 | U21: =+R21+T21 -> 0
A22: 16 | B22: DAMBROSIO RIVERO LIZETH STEFANNY | C22: ARQUITECTA | D22: 22 | F22: 6 | Q22: =SUM(E22:P22) -> 6 | R22: =+D22-Q22 -> 16 | S22: 46023 | T22: 30 | U22: =+R22+T22 -> 46
B23: DEPAZ HUERTAS, JOSE DANIEL | C23: BIM | D23: 0 | Q23: =SUM(E23:P23) -> 0 | R23: =+D23-Q23 -> 0 | S23: 46331 | U23: =+R23+T23 -> 0
A24: 19 | B24: FLORES MANTILLA MARIANA | C24: ARQUITECTA | D24: 66 | E24: 15 | Q24: =SUM(E24:P24) -> 15 | R24: =+D24-Q24 -> 51 | S24: 46235 | U24: =+R24+T24 -> 51
A25: 4 | B25: GOYAS ABRAMONTE, JAVIER ENRRIQUE | C25: ING. CIVIL | D25: 135 | Q25: =SUM(E25:P25) -> 0 | R25: =+D25-Q25 -> 135 | S25: 46113 | T25: 30 | U25: =+R25+T25 -> 165
A26: 20 | B26: GRANDE ALCANTARA MILAGROS M. | C26: ARQUITECTA | D26: -16 | Q26: =SUM(E26:P26) -> 0 | R26: =+D26-Q26 -> -16 | S26: 46204 | U26: =+R26+T26 -> -16
B27: HABICH ACUÑA, JACQUELINE | C27: ARQUITECTO | D27: 0 | Q27: =SUM(E27:P27) -> 0 | R27: =+D27-Q27 -> 0 | S27: 46301 | U27: =+R27+T27 -> 0
B28: HERMITAÑO ASPILCUETA DIEGO ALFONSO | C28: ING. CIVIL - ASIST | D28: 60 | Q28: =SUM(E28:P28) -> 0 | R28: =+D28-Q28 -> 60 | S28: 46060 | U28: =+R28+T28 -> 60
B29: LEON TORRES JHOSSELYN | C29: ARQUITECTO | D29: 30 | H29: 18 | Q29: =SUM(E29:P29) -> 18 | R29: =+D29-Q29 -> 12 | S29: 46235 | U29: =+R29+T29 -> 12
B30: MEDINA POLO, OMAR | C30: ING. CIVIL | D30: 0 | Q30: =SUM(E30:P30) -> 0 | R30: =+D30-Q30 -> 0 | S30: 46447 | U30: =+R30+T30 -> 0
B31: MIRANDA HUAMAN, MILAGROS VIRGINIA ADALETE | C31: ARQUITECTO | D31: 30 | H31: 18 | I31: 12 | Q31: =SUM(E31:P31) -> 30 | R31: =+D31-Q31 -> 0 | S31: 46163 | U31: =+R31+T31 -> 0 | X31: 259 | Y31: =X31*Y29/X29 -> #DIV/0!
B32: NEYRA CUMPA JORGAN CESAR | C32: SOFTWARE | D32: 0 | F32: 1 | G32: 3 | Q32: =SUM(E32:P32) -> 4 | R32: =+D32-Q32 -> -4 | S32: 46419 | U32: =+R32+T32 -> -4
A33: 24 | B33: OSCCO GUILLEN EDWIN RAFAEL | C33: ING. CIVIL | D33: 84 | F33: 8 | Q33: =SUM(E33:P33) -> 8 | R33: =+D33-Q33 -> 76 | S33: 46327 | U33: =+R33+T33 -> 76
B34: PESEROS MOREYRA, ALEXANDER HEINZ | C34: ARQUITECTO | D34: 0 | Q34: =SUM(E34:P34) -> 0 | R34: =+D34-Q34 -> 0 | S34: 46097 | T34: 30 | U34: =+R34+T34 -> 30
A35: 5 | B35: RAMIREZ ROMAN MARCELO | C35: ING. CIVIL | D35: 236 | Q35: =SUM(E35:O35) -> 0 | R35: =+D35-Q35 -> 236 | S35: 46204 | U35: =+R35+T35 -> 236 | AL35: =C35*40% -> #VALUE!
B36: RAMOS RAMOS, LENIN ANTHONY | C36: ING. CIVIL | D36: 0 | Q36: =SUM(E36:P36) -> 0 | R36: =+D36-Q36 -> 0 | S36: 46420 | U36: =+R36+T36 -> 0
B37: ROBLES ARIAS HARIF ALDAIR | C37: ING. CIVIL | D37: 0 | Q37: =SUM(E37:P37) -> 0 | R37: =+D37-Q37 -> 0 | S37: 46357 | U37: =+R37+T37 -> 0
A38: ruiz | B38: RUIZ LOPEZ GEYSIN | C38: ING. CIVIL | D38: 30 | F38: 7 | Q38: =SUM(E38:P38) -> 7 | R38: =+D38-Q38 -> 23 | S38: 46211 | U38: =+R38+T38 -> 23
B39: VALDEZ RODRIGUEZ, KENYI JORGE | C39: ING. CIVIL | D39: 0 | Q39: =SUM(E39:P39) -> 0 | R39: =+D39-Q39 -> 0 | S39: 46255 | U39: =+R39+T39 -> 0
B40: VILLALOBOS ZUÑIGA, DIEGO ALONSO | C40: ING. CIVIL | D40: 0 | Q40: =SUM(E40:P40) -> 0 | R40: =+D40-Q40 -> 0 | S40: 46095 | U40: =+R40+T40 -> 0
...

Sheet vacaciones 2025
B1: REPORTE DE VACACIONES
B2: EMPLEADOS | D2: SALDOS DE DIAS POR GOZAR 2024 | E2: ENE | F2: FEB | G2: MAR | H2: ABR | I2: MAY | J2: JUN | K2: JUL | L2: AGO | M2: SET | N2: OCT | O2: NOV | P2: DIC | Q2: Total días gozados | R2: PENDIENTES POR GOZAR 2024 | S2: FECHAS DE VENCIMIENTO 2025 | T2: VACACIONES POR VENCER 2025 | U2: Vacaciones Pendientes por gozar 2025
B3: AREA DE GERENCIA
A4: 2 | B4: ASPILCUETA GUTIERREZ KAREN | C4: ASISTENTE GERENCIAL | D4: ='vacaciones 2024'!U4 -> 96 | G4: 1 | I4: =1+2 -> 3 | J4: 1 | K4: 1 | Q4: =SUM(E4:P4) -> 6 | R4: =+D4-Q4 -> 90 | S4: 45735 | T4: 30 | U4: =+R4+T4 -> 120
A5: 3 | B5: GRANDE PECEROS DAVID | C5: ADMINISTRADOR | D5: ='vacaciones 2024'!U5 -> 37 | E5: 11 | F5: 4 | I5: 1 | K5: 7 | Q5: =SUM(E5:P5) -> 23 | R5: =+D5-Q5 -> 14 | S5: 45950 | T5: 30 | U5: =+R5+T5 -> 44
A6: 1 | B6: GRANDE ALCANTRA, RAUL NEVADA | C6: GERENTE GENERAL | D6: ='vacaciones 2023 '!U6 -> 0 | Q6: =SUM(E6:P6) -> 0 | R6: =+D6-Q6 -> 0 | U6: =+R6+T6 -> 0
B7: AREA DE PRESUPUESTO
A8: 7 | B8: YON UTRILLA LUIS | C8: ARQUITECTO | D8: ='vacaciones 2024'!U8 -> 113 | Q8: =SUM(E8:P8) -> 0 | R8: =+D8-Q8 -> 113 | S8: 45581 | T8: 30 | U8: =+R8+T8 -> 143
B9: VENEGAS MARCHAND FRANCISCO | C9: ING. CIVIL | K9: 21 | Q9: =SUM(E9:P9) -> 21 | R9: =+D9-Q9 -> -21 | S9: 45870 | T9: 30 | U9: =+R9+T9 -> 9
B10: OCHOA GUTIERREZ ERICKSON | C10: ING. CIVIL | D10: ='vacaciones 2024'!U9 -> -5 | F10: 25 | J10: 4 | N10: 1 | Q10: =SUM(E10:P10) -> 30 | R10: =+D10-Q10 -> -35 | S10: 45737 | T10: 30 | U10: =+R10+T10 -> -5
B11: AREA DE OPERACIONES
A12: 5 | B12: RAMIREZ ROMAN MARCELO | C12: ING. CIVIL | D12: ='vacaciones 2024'!U11 -> 240 | E12: 15 | F12: 16 | J12: 3 | Q12: =SUM(E12:O12) -> 34 | R12: =+D12-Q12 -> 206 | S12: 45840 | T12: 30 | U12: =+R12+T12 -> 236 | AL12: =C12*40% -> #VALUE!
A13: 12 | B13: BAUTISTA MOLINA LUIS FERNANDO | C13: ING. CIVIL | D13: ='vacaciones 2024'!U16 -> 118 | Q13: =SUM(E13:P13) -> 0 | R13: =+D13-Q13 -> 118 | S13: 45953 | T13: 30 | U13: =+R13+T13 -> 148
A14: 4 | B14: GOYAS ABRAMONTE, JAVIER ENRRIQUE | C14: ING. CIVIL | D14: ='vacaciones 2024'!U12 -> 115 | F14: =4+6 -> 10 | Q14: =SUM(E14:P14) -> 10 | R14: =+D14-Q14 -> 105 | S14: 45776 | T14: 30 | U14: =+R14+T14 -> 135
A15: 24 | B15: OSCCO GUILLEN EDWIN RAFAEL | C15: ING. CIVIL | D15: ='vacaciones 2024'!U14 -> 83 | E15: 7 | F15: 15 | G15: 7 | Q15: =SUM(E15:P15) -> 29 | R15: =+D15-Q15 -> 54 | S15: 45980 | T15: 30 | U15: =+R15+T15 -> 84
A16: 19 | B16: FLORES MANTILLA MARIANA | C16: ARQUITECTA | D16: ='vacaciones 2024'!U13 -> 70 | F16: 21 | K16: 5 | O16: 8 | Q16: =SUM(E16:P16) -> 34 | R16: =+D16-Q16 -> 36 | S16: 45874 | T16: 30 | U16: =+R16+T16 -> 66
B17: HERMITAÑO ASPILCUETA DIEGO ALFONSO | C17: ING. CIVIL - ASIST | D17: ='vacaciones 2024'!U40 -> 30 | Q17: =SUM(E17:P17) -> 0 | R17: =+D17-Q17 -> 30 | S17: 45890 | T17: 30 | U17: =+R17+T17 -> 60
B18: MIRANDA HUAMAN, MILAGROS VIRGINIA ADALETE | C18: ARQUITECTO | Q18: =SUM(E18:P18) -> 0 | R18: =+D18-Q18 -> 0 | S18: 45802 | T18: 30 | U18: =+R18+T18 -> 30 | X18: 259 | Y18: =X18*Y16/X16 -> #DIV/0!
B19: LEON TORRES JHOSSELYN | C19: ARQUITECTO | Q19: =SUM(E19:P19) -> 0 | R19: =+D19-Q19 -> 0 | S19: 45870 | T19: 30 | U19: =+R19+T19 -> 30
A20: ruiz | B20: RUIZ LOPEZ GEYSIN | C20: ING. CIVIL | Q20: =SUM(E20:P20) -> 0 | R20: =+D20-Q20 -> 0 | S20: 45846 | T20: 30 | U20: =+R20+T20 -> 30
B21: CARRANZA HOYOS GUILLERMO | C21: ING. CIVIL | Q21: =SUM(E21:P21) -> 0 | R21: =+D21-Q21 -> 0 | S21: 45902 | T21: 30 | U21: =+R21+T21 -> 30
B22: YUEN VENTURO CESIA SHARON | C22: ING. CIVIL | D22: ='vacaciones 2024'!U22 -> 30 | I22: 29 | N22: 7 | P22: 7 | Q22: =SUM(E22:P22) -> 43 | R22: =+D22-Q22 -> -13 | S22: 45897 | T22: 30 | U22: =+R22+T22 -> 17 | X22: 365 | Y22: 30
A23: 16 | B23: DAMBROSIO RIVERO LIZETH STEFANNY | C23: ARQUITECTA | D23: ='vacaciones 2024'!U17 -> 45 | E23: 31 | F23: 13 | I23: 2 | N23: 7 | Q23: =SUM(E23:P23) -> 53 | R23: =+D23-Q23 -> -8 | S23: 45826 | T23: 30 | U23: =+R23+T23 -> 22
A24: 11 | B24: ARROYO FALLA, VANESSA ALICIA | C24: ARQUITECTA | D24: ='vacaciones 2024'!U20 -> -9 | Q24: =SUM(E24:P24) -> 0 | R24: =+D24-Q24 -> -9 | S24: 45826 | T24: 30 | U24: =+R24+T24 -> 21 | W24: =W23-W22+1 -> 1
A25: 13 | B25: BRIONES RIVERA, RICHARD | C25: ARQUITECTO | D25: ='vacaciones 2024'!U19 -> 40 | E25: 22 | F25: 25 | P25: 14 | Q25: =SUM(E25:P25) -> 61 | R25: =+D25-Q25 -> -21 | S25: 43862 | T25: 30 | U25: =+R25+T25 -> 9 | W25: 45996
A26: 14 | B26: COLETO PASTOR LUIS ENRIQUE | C26: ING. CIVIL | D26: ='vacaciones 2024'!U18 -> 0 | E26: 12 | F26: =10+8 -> 18 | Q26: =SUM(E26:P26) -> 30 | R26: =+D26-Q26 -> -30 | S26: 45658 | T26: 30 | U26: =+R26+T26 -> 0 | W26: 45983
B27: RODRIGUEZ ZAMBRANO, ELISEO HUGO | N27: 7 | Q27: =SUM(E27:P27) -> 7 | R27: =+D27-Q27 -> -7 | S27: 46121 | U27: =+R27+T27 -> -7
A28: 20 | B28: GRANDE ALCANTARA MILAGROS M. | C28: ARQUITECTA | D28: ='vacaciones 2024'!U15 -> 59 | F28: 28 | G28: 16 | N28: 26 | O28: 30 | P28: 5 | Q28: =SUM(E28:P28) -> 105 | R28: =+D28-Q28 -> -46 | S28: 45837 | T28: 30 | U28: =+R28+T28 -> -16
B29: DE LAS CASAS DE LOS SANTOS, FABRIZIO IBRAIM | C29: ING. CIVIL | Q29: =SUM(E29:P29) -> 0 | R29: =+D29-Q29 -> 0 | S29: 46318 | U29: =+R29+T29 -> 0
B30: DEPAZ HUERTAS, JOSE DANIEL | C30: BIM | Q30: =SUM(E30:P30) -> 0 | R30: =+D30-Q30 -> 0 | S30: 46331 | U30: =+R30+T30 -> 0
B31: HABICH ACUÑA, JACQUELINE | C31: ARQUITECTO | Q31: =SUM(E31:P31) -> 0 | R31: =+D31-Q31 -> 0 | S31: 0610/2026 | U31: =+R31+T31 -> 0
B32: PESEROS MOREYRA, ALEXANDER HEINZ | C32: ARQUITECTO | Q32: =SUM(E32:P32) -> 0 | R32: =+D32-Q32 -> 0 | S32: 46097 | U32: =+R32+T32 -> 0
B33: VALDEZ RODRIGUEZ, KENYI JORGE | C33: ING. CIVIL | Q33: =SUM(E33:P33) -> 0 | R33: =+D33-Q33 -> 0 | S33: 46255 | U33: =+R33+T33 -> 0
B34: VEGA MORENO, BRYAN GERARDO | C34: ING. CIVIL | Q34: =SUM(E34:P34) -> 0 | R34: =+D34-Q34 -> 0 | S34: 46350 | U34: =+R34+T34 -> 0
B35: ZULUETA CALDERON, ROBERT ALEXANDER | C35: ING. CIVIL | Q35: =SUM(E35:P35) -> 0 | R35: =+D35-Q35 -> 0 | S35: 46255 | U35: =+R35+T35 -> 0
B36: BRAVO GARCIA CESAR OMAR | C36: ARQUITECTO | Q36: =SUM(E36:P36) -> 0 | R36: =+D36-Q36 -> 0 | S36: 46023 | U36: =+R36+T36 -> 0
B37: ROBLES ARIAS HARIF ALDAIR | C37: ING. CIVIL | S37: 46357
B38: AREA CONTABLE
A39: 27 | B39: BACA WIESSE JOSE ALBERTO | C39: CONTADOR GENERAL | D39: ='vacaciones 2024'!U27 -> 67 | E39: 1 | F39: 12 | G39: 6 | I39: 14 | P39: 10 | Q39: =SUM(E39:P39) -> 43 | R39: =+D39-Q39 -> 24 | S39: 45662 | T39: 30 | U39: =+R39+T39 -> 54 | AA39: 46013
A40: 29 | B40: GUZMAN MANTARI INGRID | C40: ASISTENTE CONTABLE | D40: ='vacaciones 2024'!U30 -> 29 | E40: 1 | F40: =1+1 -> 2 | G40: 1 | I40: 1 | K40: =5+2 -> 7 | P40: 7 | Q40: =SUM(E40:P40) -> 19 | R40: =+D40-Q40 -> 10 | S40: 45953 | T40: 30 | U40: =+R40+T40 -> 40 | AA40: 46022
...

Sheet vacaciones 2024
B1: REPORTE DE VACACIONES
B2: EMPLEADOS | D2: SALDOS DE DIAS POR GOZAR 2023 | E2: ENE | F2: FEB | G2: MAR | H2: ABR | I2: MAY | J2: JUN | K2: JUL | L2: AGO | M2: SET | N2: OCT | O2: NOV | P2: DIC | Q2: Total días gozados | R2: PENDIENTES POR GOZAR 2023 | S2: FECHAS DE VENCIMIENTO 2024 | T2: VACACIONES POR VENCER 2024 | U2: Vacaciones Pendientes por gozar 2024
B3: AREA DE GERENCIA
A4: 2 | B4: ASPILCUETA GUTIERREZ KAREN | C4: ASISTENTE GERENCIAL | D4: ='vacaciones 2023 '!U4 -> 77 | F4: 1 | L4: 6 | M4: 3 | O4: 1 | Q4: =SUM(E4:P4) -> 11 | R4: =+D4-Q4 -> 66 | S4: 45370 | T4: 30 | U4: =+R4+T4 -> 96
A5: 3 | B5: GRANDE PECEROS DAVID | C5: ADMINISTRADOR | D5: ='vacaciones 2023 '!U5 -> 75 | E5: 10 | F5: 18 | J5: 1 | K5: 14 | L5: 25 | Q5: =SUM(E5:P5) -> 68 | R5: =+D5-Q5 -> 7 | S5: 45585 | T5: 30 | U5: =+R5+T5 -> 37
A6: 1 | B6: GRANDE ALCANTRA, RAUL NEVADA | C6: GERENTE GENERAL | D6: ='vacaciones 2023 '!U6 -> 0 | Q6: =SUM(E6:P6) -> 0 | R6: =+D6-Q6 -> 0 | U6: =+R6+T6 -> 0
B7: AREA DE PRESUPUESTO
A8: 7 | B8: YON UTRILLA LUIS | C8: ARQUITECTO | D8: ='vacaciones 2023 '!U8 -> 83 | Q8: =SUM(E8:P8) -> 0 | R8: =+D8-Q8 -> 83 | S8: 45581 | T8: 30 | U8: =+R8+T8 -> 113
B9: OCHOA GUTIERREZ ERICKSON | C9: ING. CIVIL | D9: ='vacaciones 2023 '!U9 -> 10 | J9: 3 | K9: 11 | P9: =23+8 -> 31 | Q9: =SUM(E9:P9) -> 45 | R9: =+D9-Q9 -> -35 | S9: 45372 | T9: 30 | U9: =+R9+T9 -> -5
B10: AREA DE OPERACIONES
A11: 5 | B11: RAMIREZ ROMAN MARCELO | C11: ING. CIVIL | D11: ='vacaciones 2023 '!U11 -> 225 | K11: 15 | Q11: =SUM(E11:O11) -> 15 | R11: =+D11-Q11 -> 210 | S11: 45475 | T11: 30 | U11: =+R11+T11 -> 240
A12: 4 | B12: GOYAS ABRAMONTE, JAVIER ENRRIQUE | C12: ING. CIVIL | D12: ='vacaciones 2023 '!U12 -> 93 | F12: 4 | I12: 4 | Q12: =SUM(E12:P12) -> 8 | R12: =+D12-Q12 -> 85 | S12: 45411 | T12: 30 | U12: =+R12+T12 -> 115
A13: 19 | B13: FLORES MANTILLA MARIANA | C13: ARQUITECTA | D13: ='vacaciones 2023 '!U13 -> 54 | F13: 14 | Q13: =SUM(E13:P13) -> 14 | R13: =+D13-Q13 -> 40 | S13: 45509 | T13: 30 | U13: =+R13+T13 -> 70
A14: 24 | B14: OSCCO GUILLEN EDWIN RAFAEL | C14: ING. CIVIL | D14: ='vacaciones 2023 '!U14 -> 71 | E14: 15 | J14: 3 | Q14: =SUM(E14:P14) -> 18 | R14: =+D14-Q14 -> 53 | S14: 45615 | T14: 30 | U14: =+R14+T14 -> 83
A15: 20 | B15: GRANDE ALCANTARA MILAGROS M. | C15: ARQUITECTA | D15: ='vacaciones 2023 '!U15 -> 29 | Q15: =SUM(E15:P15) -> 0 | R15: =+D15-Q15 -> 29 | S15: 45472 | T15: 30 | U15: =+R15+T15 -> 59
A16: 12 | B16: BAUTISTA MOLINA LUIS FERNANDO | C16: ING. CIVIL | D16: ='vacaciones 2023 '!U16 -> 88 | Q16: =SUM(E16:P16) -> 0 | R16: =+D16-Q16 -> 88 | S16: 45588 | T16: 30 | U16: =+R16+T16 -> 118
A17: 16 | B17: DAMBROSIO RIVERO LIZETH STEFANNY | C17: ARQUITECTA | D17: ='vacaciones 2023 '!U17 -> 35 | J17: 7 | O17: 3 | P17: 10 | Q17: =SUM(E17:P17) -> 20 | R17: =+D17-Q17 -> 15 | S17: 45461 | T17: 30 | U17: =+R17+T17 -> 45
A18: 14 | B18: COLETO PASTOR LUIS ENRIQUE | C18: ING. CIVIL | D18: ='vacaciones 2023 '!U18 -> -15 | K18: 15 | Q18: =SUM(E18:P18) -> 15 | R18: =+D18-Q18 -> -30 | S18: 45292 | T18: 30 | U18: =+R18+T18 -> 0
A19: 13 | B19: BRIONES RIVERA, RICHARD | C19: ARQUITECTO | D19: ='vacaciones 2023 '!U20 -> 10 | Q19: =SUM(E19:P19) -> 0 | R19: =+D19-Q19 -> 10 | S19: 45450 | T19: 30 | U19: =+R19+T19 -> 40
A20: 11 | B20: ARROYO FALLA, VANESSA ALICIA | C20: ARQUITECTA | D20: ='vacaciones 2023 '!U21 -> -6 | G20: 12 | J20: 6 | K20: 15 | Q20: =SUM(E20:P20) -> 33 | R20: =+D20-Q20 -> -39 | S20: 45461 | T20: 30 | U20: =+R20+T20 -> -9
B21: CASTRO VALERIO HASSANAL | C21: ARQUITECTO | D21: ='vacaciones 2023 '!U22 -> 28 | G21: 7 | O21: 13 | P21: 15 | Q21: =SUM(E21:P21) -> 35 | R21: =+D21-Q21 -> -7 | S21: 45643 | T21: 30 | U21: =+R21+T21 -> 23
B22: YUEN VENTURO CESIA SHARON | C22: ING. CIVIL | D22: ='vacaciones 2023 '!U25 -> 0 | Q22: =SUM(E22:P22) -> 0 | R22: =+D22-Q22 -> 0 | S22: 45532 | T22: 30 | U22: =+R22+T22 -> 30
B23: MIRANDA HUAMAN, MILAGROS VIRGINIA ADALETE | C23: ARQUITECTO | S23: 45802 | U23: =+R23+T23 -> 0
A24: ruiz | B24: RUIZ LOPEZ GEYSIN | C24: ING. CIVIL | S24: 45846 | U24: =+R24+T24 -> 0
B25: ASCONA GUELAC BRYAN | C25: ING. MECANICO ELECTRICISTA | D25: ='vacaciones 2023 '!U33 -> 0 | Q25: =SUM(E25:P25) -> 0 | R25: =+D25-Q25 -> 0 | S25: 45353 | T25: 30 | U25: =+R25+T25 -> 30
B26: AREA CONTABLE
A27: 27 | B27: BACA WIESSE JOSE ALBERTO | C27: CONTADOR GENERAL | D27: ='vacaciones 2023 '!U35 -> 64 | F27: 19 | J27: 3 | K27: 1 | N27: 1 | O27: 2 | P27: 1 | Q27: =SUM(E27:P27) -> 27 | R27: =+D27-Q27 -> 37 | S27: 45296 | T27: 30 | U27: =+R27+T27 -> 67
B28: SANCHEZ SOTELO FIORELLA GIULIANA | C28: ASISTENTE CONTABLE | D28: ='vacaciones 2023 '!U36 -> 5 | K28: 7 | M28: =1+1 -> 2 | N28: =1+1 -> 2 | O28: 2 | P28: 14 | Q28: =SUM(E28:P28) -> 27 | R28: =+D28-Q28 -> -22 | S28: 45444 | T28: 30 | U28: =+R28+T28 -> 8 | V28: 45588
B29: VILCHEZ VIDAL ANDREA ELENA | C29: ASISTENTE CONTABLE | D29: ='vacaciones 2023 '!U37 -> 4 | K29: 6 | N29: 3 | O29: 2 | P29: 14 | Q29: =SUM(E29:P29) -> 25 | R29: =+D29-Q29 -> -21 | S29: 45444 | T29: 30 | U29: =+R29+T29 -> 9 | V29: 45596
A30: 29 | B30: GUZMAN MANTARI INGRID | C30: ASISTENTE CONTABLE | D30: ='vacaciones 2023 '!U38 -> 27 | G30: 1 | J30: 1 | L30: 1 | M30: 2 | N30: =1+1+1+1 -> 4 | O30: 2 | P30: 17 | Q30: =SUM(E30:P30) -> 28 | R30: =+D30-Q30 -> -1 | S30: 45588 | T30: 30 | U30: =+R30+T30 -> 29 | V30: =V29-V28+1 -> 9
B31: AREA DE FINANZAS
A32: 30 | B32: GRANDE ALCANTARA GERMAN N. | C32: GERENTE DE FINANZAS | D32: ='vacaciones 2023 '!U40 -> 209 | Q32: =SUM(E32:P32) -> 0 | R32: =+D32-Q32 -> 209 | S32: 45366 | T32: 30 | U32: =+R32+T32 -> 239
A33: 31 | B33: JUAN PEDRO CRUZ, GIOVANNA PAULA | C33: ASISTENTE ADMINISTRATIVO | D33: ='vacaciones 2023 '!U41 -> 26 | E33: 1 | F33: =1+2 -> 3 | G33: 1 | J33: 2 | K33: 1 | L33: 2 | M33: 1 | N33: 2 | P33: 1 | Q33: =SUM(E33:P33) -> 14 | R33: =+D33-Q33 -> 12 | S33: 45356 | T33: 30 | U33: =+R33+T33 -> 42
A34: 17 | B34: ESPEJO PACHECO, URSULA AMELIA | C34: ASISTENTE ADMINISTRATIVO | D34: ='vacaciones 2023 '!U42 -> 0 | Q34: =SUM(E34:P34) -> 0 | R34: =+D34-Q34 -> 0 | U34: =+R34+T34 -> 0
B35: AREA DE LOGISTICA
A36: 34 | B36: BAUTISTA AYESTA WALTER | C36: ADMIN. DE OBRA | D36: ='vacaciones 2023 '!U44 -> 250 | N36: 9 | O36: 30 | P36: 31 | Q36: =SUM(E36:P36) -> 70 | R36: =+D36-Q36 -> 180 | S36: 45447 | T36: 30 | U36: =+R36+T36 -> 210
A37: 33 | B37: BAUTISTA AYESTA HEBER | C37: ADMIN. DE OBRA | D37: ='vacaciones 2023 '!U45 -> 170 | F37: 15 | Q37: =SUM(E37:P37) -> 15 | R37: =+D37-Q37 -> 155 | S37: 45478 | T37: 30 | U37: =+R37+T37 -> 185
A38: 35 | B38: ALHUAY AYESTA, RAMIRO | C38: LOGISTICA | D38: ='vacaciones 2023 '!U46 -> 21 | G38: 12 | P38: 4 | Q38: =SUM(E38:P38) -> 16 | R38: =+D38-Q38 -> 5 | S38: 45586 | T38: 30 | U38: =+R38+T38 -> 35
A39: 36 | B39: GRANDE ALCANTARA PAUL | C39: LOGISTICA | D39: ='vacaciones 2023 '!U47 -> 53 | J39: 7 | K39: 11 | Q39: =SUM(E39:P39) -> 18 | R39: =+D39-Q39 -> 35 | S39: 45647 | T39: 30 | U39: =+R39+T39 -> 65
B40: HERMITAÑO ASPILCUETA DIEGO ALFONSO | C40: LOGISTICA | D40: ='vacaciones 2023 '!U48 -> 0 | S40: 45525 | T40: 30 | U40: =+R40+T40 -> 30
...

Sheet vacaciones 2023 
B1: REPORTE DE VACACIONES
B2: EMPLEADOS | D2: SALDOS DE DIAS POR GOZAR 2022 | E2: ENE | F2: FEB | G2: MAR | H2: ABR | I2: MAY | J2: JUN | K2: JUL | L2: AGO | M2: SET | N2: OCT | O2: NOV | P2: DIC | Q2: Total días gozados | R2: PENDIENTES POR GOZAR 2022 | S2: FECHAS DE VENCIMIENTO 2023 | T2: VACACIONES POR VENCER 2023 | U2: Vacaciones Pendientes por gozar 2023
B3: AREA DE GERENCIA
A4: 2 | B4: ASPILCUETA GUTIERREZ KAREN | C4: ASISTENTE GERENCIAL | D4: ='vacaciones 2022'!U4 -> 66 | E4: 1 | G4: 7 | I4: 1 | J4: 1 | K4: 7 | M4: 1 | P4: 1 | Q4: =SUM(E4:P4) -> 19 | R4: =+D4-Q4 -> 47 | S4: 45011 | T4: 30 | U4: =+R4+T4 -> 77
A5: 3 | B5: GRANDE PECEROS DAVID | C5: ADMINISTRADOR | D5: ='vacaciones 2022'!U5 -> 54 | J5: 2 | L5: 7 | Q5: =SUM(E5:P5) -> 9 | R5: =+D5-Q5 -> 45 | S5: 45226 | T5: 30 | U5: =+R5+T5 -> 75
A6: 1 | B6: GRANDE ALCANTRA, RAUL NEVADA | C6: GERENTE GENERAL | D6: ='vacaciones 2022'!U6 -> 0 | Q6: =SUM(E6:P6) -> 0 | R6: =+D6-Q6 -> 0 | U6: =+R6+T6 -> 0
B7: AREA DE PRESUPUESTO
A8: 7 | B8: YON UTRILLA LUIS | C8: ARQUITECTO | D8: ='vacaciones 2022'!U8 -> 53 | Q8: =SUM(E8:P8) -> 0 | R8: =+D8-Q8 -> 53 | S8: 45222 | T8: 30 | U8: =+R8+T8 -> 83
B9: OCHOA GUTIERREZ ERICKSON | C9: ING. CIVIL | D9: ='vacaciones 2022'!U10 -> -12 | J9: 7 | K9: 1 | Q9: =SUM(E9:P9) -> 8 | R9: =+D9-Q9 -> -20 | S9: 45006 | T9: 30 | U9: =+R9+T9 -> 10
B10: AREA DE OPERACIONES
A11: 5 | B11: RAMIREZ ROMAN MARCELO | C11: ING. CIVIL | D11: ='vacaciones 2022'!U12 -> 202 | I11: 7 | Q11: =SUM(E11:O11) -> 7 | R11: =+D11-Q11 -> 195 | S11: 45109 | T11: 30 | U11: =+R11+T11 -> 225
A12: 4 | B12: GOYAS ABRAMONTE, JAVIER ENRRIQUE | C12: ING. CIVIL | D12: ='vacaciones 2022'!U13 -> 79 | G12: 1 | H12: =7 -> 7 | I12: 6 | J12: 2 | Q12: =SUM(E12:P12) -> 16 | R12: =+D12-Q12 -> 63 | S12: 45045 | T12: 30 | U12: =+R12+T12 -> 93
A13: 19 | B13: FLORES MANTILLA MARIANA | C13: ARQUITECTA | D13: ='vacaciones 2022'!U14 -> 39 | E13: 15 | Q13: =SUM(E13:P13) -> 15 | R13: =+D13-Q13 -> 24 | S13: 45143 | T13: 30 | U13: =+R13+T13 -> 54 | V13: REGRESA A OFICINA EL 09/02/2023
A14: 24 | B14: OSCCO GUILLEN EDWIN RAFAEL | C14: ING. CIVIL | D14: ='vacaciones 2022'!U15 -> 65 | F14: 7 | J14: 3 | P14: 14 | Q14: =SUM(E14:P14) -> 24 | R14: =+D14-Q14 -> 41 | S14: 45249 | T14: 30 | U14: =+R14+T14 -> 71
A15: 20 | B15: GRANDE ALCANTARA MILAGROS M. | C15: ARQUITECTA | D15: ='vacaciones 2022'!U16 -> 60 | E15: 31 | H15: 7 | I15: 23 | Q15: =SUM(E15:P15) -> 61 | R15: =+D15-Q15 -> -1 | S15: 45106 | T15: 30 | U15: =+R15+T15 -> 29 | V15: VACACIONES DEL 01/01/2023 Y CONTANDO
A16: 12 | B16: BAUTISTA MOLINA LUIS FERNANDO | C16: ING. CIVIL | D16: ='vacaciones 2022'!U18 -> 58 | Q16: =SUM(E16:P16) -> 0 | R16: =+D16-Q16 -> 58 | S16: 45222 | T16: 30 | U16: =+R16+T16 -> 88
A17: 16 | B17: DAMBROSIO RIVERO LIZETH STEFANNY | C17: ARQUITECTA | D17: ='vacaciones 2022'!U19 -> 31 | F17: 9 | N17: 17 | Q17: =SUM(E17:P17) -> 26 | R17: =+D17-Q17 -> 5 | S17: 45095 | T17: 30 | U17: =+R17+T17 -> 35
A18: 14 | B18: COLETO PASTOR LUIS ENRIQUE | C18: ING. CIVIL | D18: ='vacaciones 2022'!U21 -> 16 | E18: 17 | F18: 29 | G18: 15 | Q18: =SUM(E18:P18) -> 61 | R18: =+D18-Q18 -> -45 | S18: 44927 | T18: 30 | U18: =+R18+T18 -> -15 | V18: LICENCIA POR PATERNIDAD HASTA LE 14/01/2023 | W18: regresa a oficina el 02/03/2023 | Y18: 45291
A19: 21 | B19: MENDOZA GARCÍA, ZINCIA | C19: ARQUITECTA | D19: ='vacaciones 2022'!U23 -> 0 | E19: 7 | Q19: =SUM(E19:P19) -> 7 | R19: =+D19-Q19 -> -7 | S19: 45083 | T19: 30 | U19: =+R19+T19 -> 23 | Y19: =Y18-Y17+1 -> 45292
A20: 13 | B20: BRIONES RIVERA, RICHARD | C20: ARQUITECTO | D20: ='vacaciones 2022'!U24 -> 2 | E20: 22 | Q20: =SUM(E20:P20) -> 22 | R20: =+D20-Q20 -> -20 | S20: 45084 | T20: 30 | U20: =+R20+T20 -> 10 | V20: REGRESA A OFICINA EL 23/01/2023
A21: 11 | B21: ARROYO FALLA, VANESSA ALICIA | C21: ARQUITECTA | D21: ='vacaciones 2022'!U25 -> -15 | J21: 12 | K21: 4 | L21: 5 | Q21: =SUM(E21:P21) -> 21 | R21: =+D21-Q21 -> -36 | S21: 45095 | T21: 30 | U21: =+R21+T21 -> -6 | V21: REGRESA A OFICINA EL 09/01/2023 - DM CVID
B22: CASTRO VALERIO HASSANAL | C22: ARQUITECTO | D22: ='vacaciones 2022'!U26 -> 20 | I22: 7 | P22: 15 | Q22: =SUM(E22:P22) -> 22 | R22: =+D22-Q22 -> -2 | S22: 45277 | T22: 30 | U22: =+R22+T22 -> 28
B23: HABICH ACUÑA, JACQUELINE | C23: ARQUITECTO | D23: ='vacaciones 2022'!U27 -> 0 | S23: 45163 | T23: 30 | U23: =+R23+T23 -> 30
B24: AGURTO MARTINEZ JOEL ARTURO | C24: ING. CIVIL | S24: 45581
B25: YUEN VENTURO CESIA SHARON | C25: ING. CIVIL | S25: 45532
B26: RUIZ LOPEZ GEYSIN YULER | S26: 45570
B27: LEANDRO CAMPOS WILFREDO JUNIOR | S27: 45518
B28: BENITES NAVARRO AGAPITO LEON | S28: 45570
B29: YVANCOVICH VASQUEZ RUBEN | S29: 45497
B30: ARAOZ TUANAMA CARR NATALY | S30: 45588
B31: JAIME HUAMAN FRANK ADAN | C31: SSOMA | S31: 45581
B32: VALEVALENZUELA VILCAMICHE JESSIC | C32: SSOMA | S32: 45536
B33: ASCONA GUELAC BRYAN | C33: ING. MECANICO ELECTRICISTA | S33: 45353 | U33: =+R33+T33 -> 0
B34: AREA CONTABLE
A35: 27 | B35: BACA WIESSE JOSE ALBERTO | C35: CONTADOR GENERAL | D35: ='vacaciones 2022'!U29-5 -> 52 | J35: 4 | L35: 1 | N35: 7 | P35: 6 | Q35: =SUM(E35:P35) -> 18 | R35: =+D35-Q35 -> 34 | S35: 44931 | T35: 30 | U35: =+R35+T35 -> 64
B36: SANCHEZ SOTELO FIORELLA GIULIANA | C36: ASISTENTE CONTABLE | D36: ='vacaciones 2022'!U30 -> -11 | K36: 7 | N36: 1 | P36: 6 | Q36: =SUM(E36:P36) -> 14 | R36: =+D36-Q36 -> -25 | S36: 45078 | T36: 30 | U36: =+R36+T36 -> 5
B37: VILCHEZ VIDAL ANDREA ELENA | C37: ASISTENTE CONTABLE | D37: ='vacaciones 2022'!U31 -> -11 | K37: 7 | M37: 1 | P37: =6+1 -> 7 | Q37: =SUM(E37:P37) -> 15 | R37: =+D37-Q37 -> -26 | S37: 45078 | T37: 30 | U37: =+R37+T37 -> 4
A38: 29 | B38: GUZMAN MANTARI INGRID | C38: ASISTENTE CONTABLE | D38: ='vacaciones 2022'!U32+5 -> 12 | G38: 1 | I38: 2 | J38: 1 | L38: 1 | M38: 1 | N38: 1 | O38: 2 | P38: 6 | Q38: =SUM(E38:P38) -> 15 | R38: =+D38-Q38 -> -3 | S38: 45222 | T38: 30 | U38: =+R38+T38 -> 27
B39: AREA DE FINANZAS
A40: 30 | B40: GRANDE ALCANTARA GERMAN N. | C40: GERENTE DE FINANZAS | D40: ='vacaciones 2022'!U34 -> 179 | Q40: =SUM(E40:P40) -> 0 | R40: =+D40-Q40 -> 179 | S40: 45000 | T40: 30 | U40: =+R40+T40 -> 209
...

Sheet vacaciones 2022
B1: REPORTE DE VACACIONES
B2: EMPLEADOS | D2: SALDOS DE DIAS POR GOZAR 2021 | E2: ENE | F2: FEB | G2: MAR | H2: ABR | I2: MAY | J2: JUN | K2: JUL | L2: AGO | M2: SET | N2: OCT | O2: NOV | P2: DIC | Q2: Total días gozados | R2: PENDIENTES POR GOZAR 2021 | S2: FECHAS DE VENCIMIENTO 2022 | T2: VACACIONES POR VENCER 2022 | U2: Vacaciones Pendientes por gozar 2022
B3: AREA DE GERENCIA
A4: 2 | B4: ASPILCUETA GUTIERREZ KAREN | C4: ASISTENTE GERENCIAL | D4: ='vacaciones 2021'!U5 -> 60 | K4: 15 | L4: 1 | M4: =1+1 -> 2 | N4: 5 | P4: 1 | Q4: =SUM(E4:P4) -> 24 | R4: =+D4-Q4 -> 36 | S4: =vacaciones!L9+360 -> 44646 | T4: 30 | U4: =+R4+T4 -> 66
A5: 3 | B5: GRANDE PECEROS DAVID | C5: ADMINISTRADOR | D5: ='vacaciones 2021'!U6 -> 33 | E5: 5 | P5: 4 | Q5: =SUM(E5:P5) -> 9 | R5: =+D5-Q5 -> 24 | S5: =vacaciones!L25+360 -> 44861 | T5: 30 | U5: =+R5+T5 -> 54
A6: 1 | B6: GRANDE ALCANTRA, RAUL NEVADA | C6: GERENTE GENERAL | D6: ='vacaciones 2021'!U4 -> 0 | Q6: =SUM(E6:P6) -> 0 | R6: =+D6-Q6 -> 0 | S6: =vacaciones!I26 -> 0 | U6: =+R6+T6 -> 0
B7: AREA DE PRESUPUESTO
A8: 7 | B8: YON UTRILLA LUIS | C8: ARQUITECTO | D8: ='vacaciones 2021'!U9 -> 34 | G8: =7 -> 7 | P8: 4 | Q8: =SUM(E8:P8) -> 11 | R8: =+D8-Q8 -> 23 | S8: =vacaciones!L42+360 -> 44857 | T8: 30 | U8: =+R8+T8 -> 53
A9: 6 | B9: OROSCO BALAREZO SILVIA | C9: ING. CIVIL | D9: ='vacaciones 2021'!U8 -> 21 | I9: 5 | N9: =1+1 -> 2 | O9: 3 | P9: 4 | Q9: =SUM(E9:P9) -> 14 | R9: =+D9-Q9 -> 7 | S9: =vacaciones!L31+360 -> 44764 | T9: 30 | U9: =+R9+T9 -> 37
B10: OCHOA GUTIERREZ ERICKSON | C10: ING. CIVIL | N10: 1 | P10: 11 | Q10: =SUM(E10:P10) -> 12 | R10: =+D10-Q10 -> -12 | S10: 45006 | U10: =+R10+T10 -> -12
B11: AREA DE OPERACIONES
A12: 5 | B12: RAMIREZ ROMAN MARCELO | C12: ING. CIVIL | D12: ='vacaciones 2021'!U15 -> 179 | O12: 7 | Q12: =SUM(E12:O12) -> 7 | R12: =+D12-Q12 -> 172 | S12: =vacaciones!L35+360 -> 44744 | T12: 30 | U12: =+R12+T12 -> 202
A13: 4 | B13: GOYAS ABRAMONTE, JAVIER ENRRIQUE | C13: ING. CIVIL | D13: ='vacaciones 2021'!U14 -> 57 | E13: 1 | G13: =1+1+1 -> 3 | O13: =1+3 -> 4 | Q13: =SUM(E13:P13) -> 8 | R13: =+D13-Q13 -> 49 | S13: =vacaciones!L21+360 -> 44680 | T13: 30 | U13: =+R13+T13 -> 79
A14: 19 | B14: FLORES MANTILLA MARIANA | C14: ARQUITECTA | D14: ='vacaciones 2021'!U16 -> 63 | F14: 15 | G14: 6 | O14: 3 | P14: 30 | Q14: =SUM(E14:P14) -> 54 | R14: =+D14-Q14 -> 9 | S14: =vacaciones!L20+360 -> 44778 | T14: 30 | U14: =+R14+T14 -> 39
A15: 24 | B15: OSCCO GUILLEN EDWIN RAFAEL | C15: ING. CIVIL | D15: ='vacaciones 2021'!U18 -> 35 | Q15: =SUM(E15:P15) -> 0 | R15: =+D15-Q15 -> 35 | S15: =vacaciones!L32+360 -> 44884.5 | T15: 30 | U15: =+R15+T15 -> 65
